SEED 1518496051
INIT_TIME 0
FIN_TIME 15000
ARRIVE_MIN 1
ARRIVE_MAX 25
QUIT_PROB 0.200000
CPU_MIN 1
CPU_MAX 5
DISK1_MIN 25
DISK1_MAX 100
DISK2_MIN 25
DISK2_MAX 100

At 0 job 1 arrived
At 0 job 1 started using the cpu
At 3 job 1 finished using the cpu
At 6 job 1 started using disk1
At 20 job 2 arrived
At 20 job 2 started using the cpu
At 21 job 2 finished using the cpu
At 41 job 3 arrived
At 41 job 3 started using the cpu
At 44 job 3 finished using the cpu
At 56 job 4 arrived
At 56 job 4 started using the cpu
At 58 job 4 finished using the cpu
At 63 job 1 finished using disk1
At 74 job 5 arrived
At 74 job 1 started using the cpu
At 79 job 1 finished using the cpu
At 88 job 3 started using disk2
At 88 job 6 arrived
At 88 job 5 started using the cpu
At 90 job 5 finished using the cpu
At 106 job 7 arrived
At 106 job 6 started using the cpu
At 108 job 6 finished using the cpu
At 125 job 8 arrived
At 125 job 7 started using the cpu
At 130 job 9 arrived
At 130 job 7 finished using the cpu
At 133 job 10 arrived
At 133 job 8 started using the cpu
At 137 job 8 finished using the cpu
At 156 job 3 finished using disk1
At 157 job 11 arrived
At 157 job 9 started using the cpu
At 158 job 4 started using disk2
At 161 job 9 finished using the cpu
At 170 job 12 arrived
At 170 job 10 started using the cpu
At 174 job 10 finished using the cpu
At 174 job 10 terminated
At 191 job 13 arrived
At 191 job 3 started using the cpu
At 194 job 3 finished using the cpu
At 209 job 14 arrived
At 209 job 11 started using the cpu
At 212 job 11 finished using the cpu
At 218 job 15 arrived
At 218 job 12 started using the cpu
At 222 job 12 finished using the cpu
At 229 job 16 arrived
At 229 job 13 started using the cpu
At 231 job 17 arrived
At 233 job 13 finished using the cpu
At 234 job 18 arrived
At 234 job 14 started using the cpu
At 238 job 14 finished using the cpu
At 246 job 4 finished using disk1
At 249 job 19 arrived
At 249 job 15 started using the cpu
At 251 job 15 finished using the cpu
At 260 job 2 started using disk1
At 268 job 20 arrived
At 268 job 16 started using the cpu
At 270 job 21 arrived
At 270 job 16 finished using the cpu
At 294 job 22 arrived
At 294 job 17 started using the cpu
At 296 job 17 finished using the cpu
At 309 job 23 arrived
At 309 job 18 started using the cpu
At 313 job 18 finished using the cpu
At 322 job 1 started using disk2
At 329 job 24 arrived
At 329 job 4 started using the cpu
At 332 job 4 finished using the cpu
At 340 job 2 finished using disk1
At 348 job 25 arrived
At 348 job 19 started using the cpu
At 350 job 26 arrived
At 353 job 19 finished using the cpu
At 366 job 27 arrived
At 366 job 20 started using the cpu
At 367 job 20 finished using the cpu
At 381 job 28 arrived
At 381 job 21 started using the cpu
At 385 job 1 finished using disk1
At 386 job 21 finished using the cpu
At 388 job 7 started using disk1
At 392 job 29 arrived
At 392 job 22 started using the cpu
At 394 job 22 finished using the cpu
At 394 job 22 terminated
At 407 job 30 arrived
At 407 job 23 started using the cpu
At 410 job 23 finished using the cpu
At 431 job 31 arrived
At 431 job 24 started using the cpu
At 432 job 24 finished using the cpu
At 456 job 32 arrived
At 456 job 2 started using the cpu
At 457 job 33 arrived
At 458 job 2 finished using the cpu
At 472 job 34 arrived
At 472 job 25 started using the cpu
At 476 job 7 finished using disk1
At 477 job 25 finished using the cpu
At 485 job 35 arrived
At 485 job 26 started using the cpu
At 487 job 26 finished using the cpu
At 491 job 36 arrived
At 491 job 27 started using the cpu
At 494 job 27 finished using the cpu
At 498 job 37 arrived
At 498 job 28 started using the cpu
At 501 job 28 finished using the cpu
At 502 job 8 started using disk1
At 517 job 38 arrived
At 517 job 1 started using the cpu
At 519 job 1 finished using the cpu
At 525 job 39 arrived
At 525 job 29 started using the cpu
At 527 job 29 finished using the cpu
At 534 job 40 arrived
At 534 job 30 started using the cpu
At 536 job 41 arrived
At 539 job 30 finished using the cpu
At 539 job 30 terminated
At 560 job 42 arrived
At 560 job 31 started using the cpu
At 562 job 31 finished using the cpu
At 574 job 43 arrived
At 574 job 32 started using the cpu
At 578 job 32 finished using the cpu
At 580 job 44 arrived
At 580 job 33 started using the cpu
At 585 job 33 finished using the cpu
At 595 job 8 finished using disk1
At 601 job 45 arrived
At 601 job 34 started using the cpu
At 605 job 34 finished using the cpu
At 613 job 46 arrived
At 613 job 7 started using the cpu
At 615 job 7 finished using the cpu
At 626 job 3 started using disk1
At 631 job 47 arrived
At 631 job 35 started using the cpu
At 635 job 35 finished using the cpu
At 644 job 48 arrived
At 644 job 36 started using the cpu
At 649 job 36 finished using the cpu
At 652 job 49 arrived
At 652 job 37 started using the cpu
At 657 job 37 finished using the cpu
At 661 job 3 finished using disk1
At 664 job 11 started using disk1
At 664 job 50 arrived
At 664 job 38 started using the cpu
At 669 job 38 finished using the cpu
At 669 job 38 terminated
At 675 job 51 arrived
At 675 job 39 started using the cpu
At 679 job 39 finished using the cpu
At 684 job 52 arrived
At 684 job 40 started using the cpu
At 685 job 40 finished using the cpu
At 705 job 11 finished using disk1
At 706 job 12 started using disk1
At 706 job 53 arrived
At 706 job 41 started using the cpu
At 708 job 41 finished using the cpu
At 729 job 54 arrived
At 729 job 42 started using the cpu
At 731 job 12 finished using disk1
At 732 job 42 finished using the cpu
At 732 job 42 terminated
At 734 job 13 started using disk1
At 753 job 55 arrived
At 753 job 43 started using the cpu
At 754 job 43 finished using the cpu
At 770 job 56 arrived
At 770 job 44 started using the cpu
At 774 job 44 finished using the cpu
At 781 job 13 finished using disk1
At 788 job 57 arrived
At 788 job 8 started using the cpu
At 791 job 8 finished using the cpu
At 807 job 58 arrived
At 807 job 45 started using the cpu
At 808 job 45 finished using the cpu
At 810 job 59 arrived
At 810 job 46 started using the cpu
At 815 job 46 finished using the cpu
At 820 job 14 started using disk1
At 829 job 60 arrived
At 829 job 47 started using the cpu
At 834 job 47 finished using the cpu
At 837 job 61 arrived
At 837 job 48 started using the cpu
At 839 job 48 finished using the cpu
At 854 job 62 arrived
At 854 job 49 started using the cpu
At 855 job 49 finished using the cpu
At 862 job 63 arrived
At 862 job 3 started using the cpu
At 864 job 5 started using disk2
At 864 job 3 finished using the cpu
At 883 job 64 arrived
At 883 job 50 started using the cpu
At 885 job 14 finished using disk1
At 886 job 50 finished using the cpu
At 895 job 65 arrived
At 895 job 51 started using the cpu
At 899 job 51 finished using the cpu
At 909 job 66 arrived
At 909 job 52 started using the cpu
At 912 job 52 finished using the cpu
At 913 job 67 arrived
At 913 job 11 started using the cpu
At 916 job 11 finished using the cpu
At 917 job 68 arrived
At 917 job 53 started using the cpu
At 919 job 53 finished using the cpu
At 931 job 69 arrived
At 931 job 54 started using the cpu
At 932 job 5 finished using disk1
At 934 job 54 finished using the cpu
At 935 job 70 arrived
At 935 job 12 started using the cpu
At 937 job 12 finished using the cpu
At 948 job 71 arrived
At 948 job 55 started using the cpu
At 951 job 55 finished using the cpu
At 954 job 6 started using disk2
At 954 job 72 arrived
At 954 job 56 started using the cpu
At 958 job 56 finished using the cpu
At 970 job 73 arrived
At 970 job 13 started using the cpu
At 971 job 13 finished using the cpu
At 987 job 74 arrived
At 987 job 57 started using the cpu
At 990 job 57 finished using the cpu
At 992 job 75 arrived
At 992 job 58 started using the cpu
At 993 job 58 finished using the cpu
At 1011 job 76 arrived
At 1011 job 59 started using the cpu
At 1016 job 59 finished using the cpu
At 1029 job 6 finished using disk1
At 1033 job 77 arrived
At 1033 job 60 started using the cpu
At 1035 job 78 arrived
At 1035 job 60 finished using the cpu
At 1035 job 60 terminated
At 1038 job 9 started using disk2
At 1053 job 79 arrived
At 1053 job 61 started using the cpu
At 1054 job 61 finished using the cpu
At 1069 job 80 arrived
At 1069 job 62 started using the cpu
At 1072 job 62 finished using the cpu
At 1072 job 62 terminated
At 1074 job 81 arrived
At 1074 job 63 started using the cpu
At 1078 job 63 finished using the cpu
At 1092 job 82 arrived
At 1092 job 64 started using the cpu
At 1095 job 64 finished using the cpu
At 1099 job 9 finished using disk1
At 1110 job 83 arrived
At 1110 job 14 started using the cpu
At 1113 job 84 arrived
At 1113 job 14 finished using the cpu
At 1115 job 85 arrived
At 1115 job 65 started using the cpu
At 1116 job 65 finished using the cpu
At 1124 job 24 started using disk2
At 1131 job 86 arrived
At 1131 job 66 started using the cpu
At 1132 job 87 arrived
At 1134 job 66 finished using the cpu
At 1155 job 88 arrived
At 1155 job 67 started using the cpu
At 1160 job 67 finished using the cpu
At 1163 job 89 arrived
At 1163 job 68 started using the cpu
At 1166 job 68 finished using the cpu
At 1173 job 90 arrived
At 1173 job 69 started using the cpu
At 1177 job 69 finished using the cpu
At 1177 job 69 terminated
At 1186 job 24 finished using disk1
At 1186 job 91 arrived
At 1186 job 5 started using the cpu
At 1190 job 5 finished using the cpu
At 1209 job 92 arrived
At 1209 job 70 started using the cpu
At 1210 job 2 started using disk2
At 1213 job 70 finished using the cpu
At 1213 job 70 terminated
At 1222 job 93 arrived
At 1222 job 71 started using the cpu
At 1226 job 71 finished using the cpu
At 1238 job 94 arrived
At 1238 job 72 started using the cpu
At 1240 job 72 finished using the cpu
At 1250 job 2 finished using disk1
At 1257 job 95 arrived
At 1257 job 73 started using the cpu
At 1261 job 73 finished using the cpu
At 1270 job 25 started using disk2
At 1282 job 96 arrived
At 1282 job 74 started using the cpu
At 1285 job 74 finished using the cpu
At 1300 job 97 arrived
At 1300 job 75 started using the cpu
At 1304 job 75 finished using the cpu
At 1325 job 98 arrived
At 1325 job 76 started using the cpu
At 1330 job 76 finished using the cpu
At 1346 job 99 arrived
At 1346 job 6 started using the cpu
At 1347 job 6 finished using the cpu
At 1347 job 6 terminated
At 1349 job 100 arrived
At 1349 job 77 started using the cpu
At 1351 job 77 finished using the cpu
At 1357 job 101 arrived
At 1357 job 78 started using the cpu
At 1360 job 78 finished using the cpu
At 1360 job 78 terminated
At 1363 job 25 finished using disk1
At 1370 job 26 started using disk2
At 1379 job 102 arrived
At 1379 job 79 started using the cpu
At 1381 job 79 finished using the cpu
At 1404 job 103 arrived
At 1404 job 80 started using the cpu
At 1407 job 80 finished using the cpu
At 1422 job 104 arrived
At 1422 job 81 started using the cpu
At 1426 job 81 finished using the cpu
At 1426 job 81 terminated
At 1433 job 105 arrived
At 1433 job 82 started using the cpu
At 1434 job 26 finished using disk1
At 1437 job 82 finished using the cpu
At 1449 job 106 arrived
At 1449 job 9 started using the cpu
At 1452 job 9 finished using the cpu
At 1458 job 107 arrived
At 1458 job 83 started using the cpu
At 1461 job 83 finished using the cpu
At 1461 job 83 terminated
At 1468 job 108 arrived
At 1468 job 84 started using the cpu
At 1471 job 84 finished using the cpu
At 1475 job 109 arrived
At 1475 job 85 started using the cpu
At 1478 job 85 finished using the cpu
At 1478 job 85 terminated
At 1486 job 110 arrived
At 1486 job 86 started using the cpu
At 1487 job 86 finished using the cpu
At 1505 job 111 arrived
At 1505 job 87 started using the cpu
At 1508 job 27 started using disk2
At 1509 job 87 finished using the cpu
At 1520 job 112 arrived
At 1520 job 88 started using the cpu
At 1525 job 88 finished using the cpu
At 1533 job 113 arrived
At 1533 job 89 started using the cpu
At 1535 job 89 finished using the cpu
At 1540 job 114 arrived
At 1540 job 90 started using the cpu
At 1545 job 90 finished using the cpu
At 1560 job 115 arrived
At 1560 job 24 started using the cpu
At 1565 job 24 finished using the cpu
At 1568 job 27 finished using disk1
At 1572 job 116 arrived
At 1572 job 91 started using the cpu
At 1574 job 91 finished using the cpu
At 1582 job 28 started using disk2
At 1594 job 117 arrived
At 1594 job 92 started using the cpu
At 1599 job 92 finished using the cpu
At 1603 job 118 arrived
At 1603 job 93 started using the cpu
At 1605 job 93 finished using the cpu
At 1611 job 119 arrived
At 1611 job 94 started using the cpu
At 1612 job 94 finished using the cpu
At 1617 job 120 arrived
At 1617 job 2 started using the cpu
At 1621 job 2 finished using the cpu
At 1628 job 121 arrived
At 1628 job 95 started using the cpu
At 1629 job 122 arrived
At 1633 job 95 finished using the cpu
At 1636 job 123 arrived
At 1636 job 96 started using the cpu
At 1637 job 124 arrived
At 1641 job 96 finished using the cpu
At 1659 job 28 finished using disk1
At 1659 job 125 arrived
At 1659 job 97 started using the cpu
At 1662 job 97 finished using the cpu
At 1662 job 97 terminated
At 1668 job 1 started using disk2
At 1670 job 126 arrived
At 1670 job 98 started using the cpu
At 1674 job 98 finished using the cpu
At 1676 job 127 arrived
At 1676 job 99 started using the cpu
At 1679 job 128 arrived
At 1681 job 99 finished using the cpu
At 1701 job 129 arrived
At 1701 job 100 started using the cpu
At 1704 job 100 finished using the cpu
At 1711 job 1 finished using disk1
At 1711 job 130 arrived
At 1711 job 101 started using the cpu
At 1716 job 101 finished using the cpu
At 1728 job 29 started using disk2
At 1729 job 131 arrived
At 1729 job 25 started using the cpu
At 1732 job 25 finished using the cpu
At 1736 job 132 arrived
At 1736 job 102 started using the cpu
At 1738 job 102 finished using the cpu
At 1738 job 102 terminated
At 1753 job 133 arrived
At 1753 job 103 started using the cpu
At 1758 job 103 finished using the cpu
At 1771 job 134 arrived
At 1771 job 104 started using the cpu
At 1776 job 104 finished using the cpu
At 1789 job 135 arrived
At 1789 job 105 started using the cpu
At 1794 job 105 finished using the cpu
At 1794 job 105 terminated
At 1795 job 136 arrived
At 1795 job 26 started using the cpu
At 1800 job 26 finished using the cpu
At 1808 job 137 arrived
At 1808 job 106 started using the cpu
At 1809 job 138 arrived
At 1811 job 106 finished using the cpu
At 1811 job 106 terminated
At 1811 job 139 arrived
At 1811 job 107 started using the cpu
At 1813 job 107 finished using the cpu
At 1826 job 29 finished using disk1
At 1827 job 140 arrived
At 1827 job 108 started using the cpu
At 1828 job 108 finished using the cpu
At 1828 job 108 terminated
At 1832 job 31 started using disk2
At 1846 job 141 arrived
At 1846 job 109 started using the cpu
At 1850 job 109 finished using the cpu
At 1859 job 142 arrived
At 1859 job 110 started using the cpu
At 1864 job 143 arrived
At 1864 job 110 finished using the cpu
At 1864 job 110 terminated
At 1876 job 144 arrived
At 1876 job 111 started using the cpu
At 1881 job 111 finished using the cpu
At 1885 job 145 arrived
At 1885 job 112 started using the cpu
At 1889 job 112 finished using the cpu
At 1898 job 146 arrived
At 1898 job 113 started using the cpu
At 1903 job 113 finished using the cpu
At 1912 job 147 arrived
At 1912 job 114 started using the cpu
At 1916 job 114 finished using the cpu
At 1922 job 148 arrived
At 1922 job 115 started using the cpu
At 1927 job 115 finished using the cpu
At 1931 job 31 finished using disk1
At 1933 job 149 arrived
At 1933 job 27 started using the cpu
At 1936 job 27 finished using the cpu
At 1942 job 32 started using disk2
At 1947 job 150 arrived
At 1947 job 116 started using the cpu
At 1949 job 116 finished using the cpu
At 1960 job 151 arrived
At 1960 job 117 started using the cpu
At 1961 job 117 finished using the cpu
At 1982 job 152 arrived
At 1982 job 118 started using the cpu
At 1983 job 118 finished using the cpu
At 1987 job 153 arrived
At 1987 job 119 started using the cpu
At 1989 job 154 arrived
At 1992 job 119 finished using the cpu
At 1992 job 119 terminated
At 2003 job 155 arrived
At 2003 job 120 started using the cpu
At 2005 job 32 finished using disk1
At 2006 job 120 finished using the cpu
At 2019 job 156 arrived
At 2019 job 121 started using the cpu
At 2021 job 121 finished using the cpu
At 2032 job 33 started using disk2
At 2033 job 157 arrived
At 2033 job 122 started using the cpu
At 2037 job 122 finished using the cpu
At 2044 job 158 arrived
At 2044 job 123 started using the cpu
At 2048 job 123 finished using the cpu
At 2064 job 159 arrived
At 2064 job 124 started using the cpu
At 2066 job 124 finished using the cpu
At 2087 job 160 arrived
At 2087 job 28 started using the cpu
At 2090 job 28 finished using the cpu
At 2102 job 33 finished using disk1
At 2102 job 161 arrived
At 2102 job 125 started using the cpu
At 2103 job 125 finished using the cpu
At 2105 job 162 arrived
At 2105 job 126 started using the cpu
At 2107 job 126 finished using the cpu
At 2108 job 34 started using disk2
At 2109 job 163 arrived
At 2109 job 127 started using the cpu
At 2113 job 127 finished using the cpu
At 2113 job 127 terminated
At 2126 job 164 arrived
At 2126 job 128 started using the cpu
At 2129 job 128 finished using the cpu
At 2133 job 165 arrived
At 2133 job 129 started using the cpu
At 2137 job 129 finished using the cpu
At 2147 job 166 arrived
At 2147 job 1 started using the cpu
At 2149 job 167 arrived
At 2150 job 1 finished using the cpu
At 2155 job 168 arrived
At 2155 job 130 started using the cpu
At 2159 job 130 finished using the cpu
At 2159 job 130 terminated
At 2176 job 169 arrived
At 2176 job 131 started using the cpu
At 2177 job 131 finished using the cpu
At 2177 job 131 terminated
At 2182 job 170 arrived
At 2182 job 132 started using the cpu
At 2185 job 132 finished using the cpu
At 2186 job 171 arrived
At 2186 job 133 started using the cpu
At 2187 job 172 arrived
At 2188 job 34 finished using disk1
At 2190 job 7 started using disk2
At 2190 job 133 finished using the cpu
At 2190 job 133 terminated
At 2210 job 173 arrived
At 2210 job 134 started using the cpu
At 2211 job 174 arrived
At 2214 job 134 finished using the cpu
At 2227 job 175 arrived
At 2227 job 135 started using the cpu
At 2228 job 135 finished using the cpu
At 2242 job 176 arrived
At 2242 job 136 started using the cpu
At 2246 job 136 finished using the cpu
At 2265 job 177 arrived
At 2265 job 137 started using the cpu
At 2269 job 137 finished using the cpu
At 2278 job 7 finished using disk1
At 2279 job 178 arrived
At 2279 job 138 started using the cpu
At 2280 job 138 finished using the cpu
At 2294 job 179 arrived
At 2294 job 139 started using the cpu
At 2296 job 180 arrived
At 2297 job 139 finished using the cpu
At 2320 job 35 started using disk2
At 2321 job 181 arrived
At 2321 job 29 started using the cpu
At 2326 job 29 finished using the cpu
At 2326 job 29 terminated
At 2332 job 15 started using disk1
At 2346 job 182 arrived
At 2346 job 140 started using the cpu
At 2349 job 140 finished using the cpu
At 2349 job 140 terminated
At 2358 job 183 arrived
At 2358 job 141 started using the cpu
At 2363 job 141 finished using the cpu
At 2369 job 184 arrived
At 2369 job 142 started using the cpu
At 2373 job 142 finished using the cpu
At 2375 job 15 finished using disk1
At 2380 job 16 started using disk1
At 2381 job 185 arrived
At 2381 job 143 started using the cpu
At 2382 job 35 finished using disk1
At 2382 job 143 finished using the cpu
At 2396 job 186 arrived
At 2396 job 144 started using the cpu
At 2397 job 144 finished using the cpu
At 2397 job 144 terminated
At 2409 job 187 arrived
At 2409 job 145 started using the cpu
At 2410 job 188 arrived
At 2413 job 145 finished using the cpu
At 2420 job 189 arrived
At 2420 job 146 started using the cpu
At 2421 job 146 finished using the cpu
At 2426 job 190 arrived
At 2426 job 147 started using the cpu
At 2431 job 147 finished using the cpu
At 2434 job 16 finished using disk1
At 2434 job 191 arrived
At 2434 job 148 started using the cpu
At 2438 job 148 finished using the cpu
At 2451 job 192 arrived
At 2451 job 31 started using the cpu
At 2452 job 17 started using disk1
At 2455 job 193 arrived
At 2456 job 31 finished using the cpu
At 2473 job 194 arrived
At 2473 job 149 started using the cpu
At 2477 job 149 finished using the cpu
At 2477 job 149 terminated
At 2491 job 195 arrived
At 2491 job 150 started using the cpu
At 2495 job 150 finished using the cpu
At 2497 job 196 arrived
At 2497 job 151 started using the cpu
At 2501 job 151 finished using the cpu
At 2517 job 197 arrived
At 2517 job 152 started using the cpu
At 2520 job 152 finished using the cpu
At 2539 job 198 arrived
At 2539 job 153 started using the cpu
At 2544 job 153 finished using the cpu
At 2546 job 17 finished using disk1
At 2547 job 199 arrived
At 2547 job 154 started using the cpu
At 2548 job 154 finished using the cpu
At 2565 job 200 arrived
At 2565 job 155 started using the cpu
At 2566 job 155 finished using the cpu
At 2570 job 18 started using disk1
At 2575 job 201 arrived
At 2575 job 32 started using the cpu
At 2580 job 32 finished using the cpu
At 2580 job 32 terminated
At 2591 job 202 arrived
At 2591 job 156 started using the cpu
At 2596 job 156 finished using the cpu
At 2603 job 203 arrived
At 2603 job 157 started using the cpu
At 2605 job 157 finished using the cpu
At 2624 job 204 arrived
At 2624 job 158 started using the cpu
At 2626 job 158 finished using the cpu
At 2640 job 205 arrived
At 2640 job 159 started using the cpu
At 2641 job 159 finished using the cpu
At 2663 job 206 arrived
At 2663 job 160 started using the cpu
At 2664 job 160 finished using the cpu
At 2669 job 18 finished using disk1
At 2681 job 207 arrived
At 2681 job 33 started using the cpu
At 2686 job 33 finished using the cpu
At 2686 job 33 terminated
At 2697 job 208 arrived
At 2697 job 161 started using the cpu
At 2698 job 161 finished using the cpu
At 2702 job 4 started using disk1
At 2722 job 209 arrived
At 2722 job 162 started using the cpu
At 2723 job 162 finished using the cpu
At 2738 job 210 arrived
At 2738 job 163 started using the cpu
At 2742 job 211 arrived
At 2742 job 163 finished using the cpu
At 2743 job 212 arrived
At 2743 job 164 started using the cpu
At 2748 job 164 finished using the cpu
At 2748 job 164 terminated
At 2768 job 213 arrived
At 2768 job 165 started using the cpu
At 2772 job 165 finished using the cpu
At 2777 job 214 arrived
At 2777 job 166 started using the cpu
At 2781 job 166 finished using the cpu
At 2789 job 4 finished using disk1
At 2789 job 215 arrived
At 2789 job 167 started using the cpu
At 2793 job 167 finished using the cpu
At 2798 job 216 arrived
At 2798 job 168 started using the cpu
At 2799 job 217 arrived
At 2802 job 168 finished using the cpu
At 2813 job 218 arrived
At 2813 job 169 started using the cpu
At 2814 job 19 started using disk1
At 2814 job 169 finished using the cpu
At 2829 job 219 arrived
At 2829 job 170 started using the cpu
At 2834 job 220 arrived
At 2834 job 170 finished using the cpu
At 2852 job 221 arrived
At 2852 job 171 started using the cpu
At 2855 job 171 finished using the cpu
At 2859 job 19 finished using disk1
At 2869 job 222 arrived
At 2869 job 172 started using the cpu
At 2871 job 172 finished using the cpu
At 2874 job 20 started using disk1
At 2891 job 223 arrived
At 2891 job 34 started using the cpu
At 2894 job 34 finished using the cpu
At 2894 job 34 terminated
At 2907 job 224 arrived
At 2907 job 173 started using the cpu
At 2908 job 173 finished using the cpu
At 2909 job 225 arrived
At 2909 job 174 started using the cpu
At 2911 job 174 finished using the cpu
At 2924 job 226 arrived
At 2924 job 175 started using the cpu
At 2926 job 175 finished using the cpu
At 2926 job 175 terminated
At 2947 job 227 arrived
At 2947 job 176 started using the cpu
At 2952 job 176 finished using the cpu
At 2965 job 20 finished using disk1
At 2970 job 228 arrived
At 2970 job 177 started using the cpu
At 2974 job 21 started using disk1
At 2975 job 177 finished using the cpu
At 2995 job 229 arrived
At 2995 job 7 started using the cpu
At 2997 job 7 finished using the cpu
At 3018 job 230 arrived
At 3018 job 178 started using the cpu
At 3023 job 178 finished using the cpu
At 3033 job 231 arrived
At 3033 job 179 started using the cpu
At 3034 job 179 finished using the cpu
At 3034 job 179 terminated
At 3047 job 232 arrived
At 3047 job 180 started using the cpu
At 3051 job 180 finished using the cpu
At 3051 job 180 terminated
At 3054 job 233 arrived
At 3054 job 181 started using the cpu
At 3055 job 181 finished using the cpu
At 3068 job 21 finished using disk1
At 3070 job 23 started using disk1
At 3079 job 234 arrived
At 3079 job 182 started using the cpu
At 3080 job 182 finished using the cpu
At 3080 job 182 terminated
At 3097 job 235 arrived
At 3097 job 183 started using the cpu
At 3101 job 183 finished using the cpu
At 3101 job 183 terminated
At 3116 job 236 arrived
At 3116 job 184 started using the cpu
At 3119 job 184 finished using the cpu
At 3136 job 237 arrived
At 3136 job 15 started using the cpu
At 3141 job 15 finished using the cpu
At 3148 job 238 arrived
At 3148 job 185 started using the cpu
At 3150 job 185 finished using the cpu
At 3162 job 23 finished using disk1
At 3164 job 239 arrived
At 3164 job 35 started using the cpu
At 3167 job 35 finished using the cpu
At 3179 job 240 arrived
At 3179 job 186 started using the cpu
At 3182 job 186 finished using the cpu
At 3185 job 241 arrived
At 3185 job 187 started using the cpu
At 3188 job 187 finished using the cpu
At 3188 job 187 terminated
At 3198 job 68 started using disk1
At 3205 job 242 arrived
At 3205 job 188 started using the cpu
At 3209 job 188 finished using the cpu
At 3211 job 243 arrived
At 3211 job 189 started using the cpu
At 3214 job 244 arrived
At 3215 job 189 finished using the cpu
At 3215 job 189 terminated
At 3239 job 245 arrived
At 3239 job 190 started using the cpu
At 3241 job 190 finished using the cpu
At 3241 job 190 terminated
At 3250 job 246 arrived
At 3250 job 16 started using the cpu
At 3251 job 16 finished using the cpu
At 3258 job 68 finished using disk1
At 3266 job 5 started using disk1
At 3271 job 247 arrived
At 3271 job 191 started using the cpu
At 3275 job 191 finished using the cpu
At 3292 job 248 arrived
At 3292 job 192 started using the cpu
At 3294 job 192 finished using the cpu
At 3301 job 249 arrived
At 3301 job 193 started using the cpu
At 3304 job 193 finished using the cpu
At 3304 job 193 terminated
At 3315 job 5 finished using disk1
At 3326 job 250 arrived
At 3326 job 194 started using the cpu
At 3330 job 194 finished using the cpu
At 3330 job 194 terminated
At 3345 job 251 arrived
At 3345 job 195 started using the cpu
At 3348 job 71 started using disk1
At 3348 job 195 finished using the cpu
At 3353 job 252 arrived
At 3353 job 196 started using the cpu
At 3356 job 253 arrived
At 3357 job 196 finished using the cpu
At 3364 job 254 arrived
At 3364 job 197 started using the cpu
At 3368 job 197 finished using the cpu
At 3370 job 255 arrived
At 3370 job 198 started using the cpu
At 3371 job 198 finished using the cpu
At 3372 job 256 arrived
At 3372 job 17 started using the cpu
At 3376 job 17 finished using the cpu
At 3378 job 71 finished using disk1
At 3387 job 257 arrived
At 3387 job 199 started using the cpu
At 3388 job 199 finished using the cpu
At 3408 job 72 started using disk1
At 3410 job 258 arrived
At 3410 job 200 started using the cpu
At 3415 job 200 finished using the cpu
At 3435 job 259 arrived
At 3435 job 201 started using the cpu
At 3436 job 201 finished using the cpu
At 3449 job 260 arrived
At 3449 job 202 started using the cpu
At 3453 job 202 finished using the cpu
At 3457 job 261 arrived
At 3457 job 203 started using the cpu
At 3458 job 203 finished using the cpu
At 3458 job 203 terminated
At 3459 job 262 arrived
At 3459 job 204 started using the cpu
At 3460 job 204 finished using the cpu
At 3484 job 263 arrived
At 3484 job 205 started using the cpu
At 3486 job 72 finished using disk1
At 3489 job 264 arrived
At 3489 job 205 finished using the cpu
At 3491 job 265 arrived
At 3491 job 206 started using the cpu
At 3494 job 206 finished using the cpu
At 3494 job 206 terminated
At 3496 job 266 arrived
At 3496 job 18 started using the cpu
At 3497 job 18 finished using the cpu
At 3509 job 267 arrived
At 3509 job 207 started using the cpu
At 3514 job 207 finished using the cpu
At 3516 job 73 started using disk1
At 3525 job 268 arrived
At 3525 job 208 started using the cpu
At 3527 job 208 finished using the cpu
At 3536 job 269 arrived
At 3536 job 209 started using the cpu
At 3538 job 209 finished using the cpu
At 3556 job 270 arrived
At 3556 job 210 started using the cpu
At 3561 job 210 finished using the cpu
At 3562 job 271 arrived
At 3562 job 211 started using the cpu
At 3565 job 211 finished using the cpu
At 3565 job 211 terminated
At 3573 job 272 arrived
At 3573 job 212 started using the cpu
At 3576 job 212 finished using the cpu
At 3595 job 273 arrived
At 3595 job 213 started using the cpu
At 3596 job 213 finished using the cpu
At 3606 job 73 finished using disk1
At 3619 job 274 arrived
At 3619 job 214 started using the cpu
At 3623 job 214 finished using the cpu
At 3626 job 74 started using disk1
At 3629 job 275 arrived
At 3629 job 4 started using the cpu
At 3632 job 4 finished using the cpu
At 3635 job 276 arrived
At 3635 job 215 started using the cpu
At 3638 job 215 finished using the cpu
At 3649 job 277 arrived
At 3649 job 216 started using the cpu
At 3650 job 216 finished using the cpu
At 3674 job 278 arrived
At 3674 job 217 started using the cpu
At 3678 job 217 finished using the cpu
At 3684 job 279 arrived
At 3684 job 218 started using the cpu
At 3685 job 218 finished using the cpu
At 3690 job 280 arrived
At 3690 job 219 started using the cpu
At 3692 job 219 finished using the cpu
At 3703 job 281 arrived
At 3703 job 220 started using the cpu
At 3705 job 220 finished using the cpu
At 3706 job 74 finished using disk1
At 3727 job 282 arrived
At 3727 job 221 started using the cpu
At 3731 job 221 finished using the cpu
At 3731 job 221 terminated
At 3749 job 283 arrived
At 3749 job 19 started using the cpu
At 3753 job 19 finished using the cpu
At 3762 job 75 started using disk1
At 3771 job 284 arrived
At 3771 job 222 started using the cpu
At 3773 job 222 finished using the cpu
At 3776 job 285 arrived
At 3776 job 223 started using the cpu
At 3781 job 223 finished using the cpu
At 3788 job 286 arrived
At 3788 job 224 started using the cpu
At 3792 job 224 finished using the cpu
At 3813 job 287 arrived
At 3813 job 225 started using the cpu
At 3814 job 75 finished using disk1
At 3817 job 225 finished using the cpu
At 3832 job 76 started using disk1
At 3837 job 288 arrived
At 3837 job 226 started using the cpu
At 3841 job 226 finished using the cpu
At 3841 job 226 terminated
At 3850 job 289 arrived
At 3850 job 227 started using the cpu
At 3854 job 227 finished using the cpu
At 3860 job 290 arrived
At 3860 job 20 started using the cpu
At 3865 job 20 finished using the cpu
At 3870 job 291 arrived
At 3870 job 228 started using the cpu
At 3873 job 292 arrived
At 3873 job 228 finished using the cpu
At 3891 job 293 arrived
At 3891 job 229 started using the cpu
At 3892 job 76 finished using disk1
At 3896 job 229 finished using the cpu
At 3898 job 77 started using disk1
At 3909 job 294 arrived
At 3909 job 230 started using the cpu
At 3910 job 295 arrived
At 3914 job 230 finished using the cpu
At 3914 job 230 terminated
At 3919 job 296 arrived
At 3919 job 231 started using the cpu
At 3924 job 231 finished using the cpu
At 3924 job 231 terminated
At 3928 job 297 arrived
At 3928 job 232 started using the cpu
At 3932 job 232 finished using the cpu
At 3933 job 298 arrived
At 3933 job 233 started using the cpu
At 3938 job 233 finished using the cpu
At 3938 job 233 terminated
At 3957 job 299 arrived
At 3957 job 21 started using the cpu
At 3961 job 21 finished using the cpu
At 3966 job 77 finished using disk1
At 3974 job 300 arrived
At 3974 job 234 started using the cpu
At 3978 job 234 finished using the cpu
At 3978 job 234 terminated
At 3981 job 301 arrived
At 3981 job 235 started using the cpu
At 3986 job 235 finished using the cpu
At 3998 job 302 arrived
At 3998 job 236 started using the cpu
At 3999 job 303 arrived
At 4001 job 236 finished using the cpu
At 4006 job 304 arrived
At 4006 job 237 started using the cpu
At 4007 job 305 arrived
At 4007 job 237 finished using the cpu
At 4011 job 306 arrived
At 4011 job 238 started using the cpu
At 4012 job 79 started using disk1
At 4012 job 238 finished using the cpu
At 4036 job 307 arrived
At 4036 job 23 started using the cpu
At 4040 job 23 finished using the cpu
At 4049 job 308 arrived
At 4049 job 239 started using the cpu
At 4054 job 239 finished using the cpu
At 4054 job 239 terminated
At 4066 job 309 arrived
At 4066 job 240 started using the cpu
At 4070 job 240 finished using the cpu
At 4081 job 310 arrived
At 4081 job 241 started using the cpu
At 4083 job 241 finished using the cpu
At 4085 job 311 arrived
At 4085 job 242 started using the cpu
At 4089 job 242 finished using the cpu
At 4110 job 312 arrived
At 4110 job 243 started using the cpu
At 4111 job 79 finished using disk1
At 4115 job 243 finished using the cpu
At 4126 job 313 arrived
At 4126 job 244 started using the cpu
At 4128 job 244 finished using the cpu
At 4128 job 244 terminated
At 4132 job 80 started using disk1
At 4136 job 314 arrived
At 4136 job 245 started using the cpu
At 4139 job 245 finished using the cpu
At 4152 job 315 arrived
At 4152 job 246 started using the cpu
At 4154 job 246 finished using the cpu
At 4154 job 246 terminated
At 4157 job 80 finished using disk1
At 4173 job 316 arrived
At 4173 job 68 started using the cpu
At 4174 job 317 arrived
At 4177 job 68 finished using the cpu
At 4177 job 68 terminated
At 4177 job 318 arrived
At 4177 job 247 started using the cpu
At 4180 job 82 started using disk1
At 4182 job 247 finished using the cpu
At 4191 job 319 arrived
At 4191 job 248 started using the cpu
At 4192 job 248 finished using the cpu
At 4214 job 320 arrived
At 4214 job 249 started using the cpu
At 4219 job 249 finished using the cpu
At 4223 job 82 finished using disk1
At 4237 job 321 arrived
At 4237 job 5 started using the cpu
At 4238 job 5 finished using the cpu
At 4249 job 322 arrived
At 4249 job 250 started using the cpu
At 4250 job 250 finished using the cpu
At 4258 job 9 started using disk1
At 4267 job 323 arrived
At 4267 job 251 started using the cpu
At 4268 job 251 finished using the cpu
At 4269 job 324 arrived
At 4269 job 252 started using the cpu
At 4270 job 252 finished using the cpu
At 4290 job 325 arrived
At 4290 job 253 started using the cpu
At 4293 job 253 finished using the cpu
At 4306 job 326 arrived
At 4306 job 254 started using the cpu
At 4309 job 254 finished using the cpu
At 4315 job 327 arrived
At 4315 job 255 started using the cpu
At 4318 job 255 finished using the cpu
At 4327 job 328 arrived
At 4327 job 256 started using the cpu
At 4329 job 256 finished using the cpu
At 4335 job 329 arrived
At 4335 job 71 started using the cpu
At 4338 job 9 finished using disk1
At 4339 job 71 finished using the cpu
At 4342 job 330 arrived
At 4342 job 257 started using the cpu
At 4347 job 331 arrived
At 4347 job 257 finished using the cpu
At 4366 job 332 arrived
At 4366 job 258 started using the cpu
At 4367 job 333 arrived
At 4370 job 84 started using disk1
At 4371 job 258 finished using the cpu
At 4377 job 334 arrived
At 4377 job 259 started using the cpu
At 4382 job 259 finished using the cpu
At 4390 job 335 arrived
At 4390 job 260 started using the cpu
At 4392 job 336 arrived
At 4392 job 260 finished using the cpu
At 4416 job 337 arrived
At 4416 job 261 started using the cpu
At 4417 job 261 finished using the cpu
At 4423 job 338 arrived
At 4423 job 262 started using the cpu
At 4428 job 262 finished using the cpu
At 4428 job 262 terminated
At 4441 job 339 arrived
At 4441 job 263 started using the cpu
At 4443 job 263 finished using the cpu
At 4443 job 263 terminated
At 4447 job 340 arrived
At 4447 job 72 started using the cpu
At 4452 job 72 finished using the cpu
At 4459 job 84 finished using disk1
At 4460 job 341 arrived
At 4460 job 264 started using the cpu
At 4464 job 264 finished using the cpu
At 4481 job 342 arrived
At 4481 job 265 started using the cpu
At 4483 job 343 arrived
At 4484 job 265 finished using the cpu
At 4484 job 265 terminated
At 4489 job 344 arrived
At 4489 job 266 started using the cpu
At 4491 job 266 finished using the cpu
At 4492 job 86 started using disk1
At 4504 job 345 arrived
At 4504 job 267 started using the cpu
At 4509 job 267 finished using the cpu
At 4522 job 346 arrived
At 4522 job 268 started using the cpu
At 4523 job 268 finished using the cpu
At 4523 job 268 terminated
At 4528 job 347 arrived
At 4528 job 269 started using the cpu
At 4532 job 348 arrived
At 4533 job 269 finished using the cpu
At 4533 job 269 terminated
At 4536 job 86 finished using disk1
At 4536 job 349 arrived
At 4536 job 270 started using the cpu
At 4537 job 270 finished using the cpu
At 4538 job 87 started using disk1
At 4541 job 350 arrived
At 4541 job 271 started using the cpu
At 4542 job 351 arrived
At 4545 job 271 finished using the cpu
At 4545 job 271 terminated
At 4560 job 352 arrived
At 4560 job 272 started using the cpu
At 4563 job 353 arrived
At 4565 job 272 finished using the cpu
At 4573 job 354 arrived
At 4573 job 273 started using the cpu
At 4575 job 273 finished using the cpu
At 4576 job 87 finished using disk1
At 4594 job 88 started using disk1
At 4597 job 355 arrived
At 4597 job 73 started using the cpu
At 4599 job 73 finished using the cpu
At 4604 job 356 arrived
At 4604 job 274 started using the cpu
At 4605 job 274 finished using the cpu
At 4605 job 274 terminated
At 4616 job 357 arrived
At 4616 job 275 started using the cpu
At 4620 job 275 finished using the cpu
At 4620 job 275 terminated
At 4622 job 358 arrived
At 4622 job 276 started using the cpu
At 4623 job 276 finished using the cpu
At 4626 job 359 arrived
At 4626 job 277 started using the cpu
At 4629 job 360 arrived
At 4630 job 277 finished using the cpu
At 4630 job 277 terminated
At 4646 job 88 finished using disk1
At 4650 job 361 arrived
At 4650 job 278 started using the cpu
At 4653 job 278 finished using the cpu
At 4654 job 362 arrived
At 4654 job 279 started using the cpu
At 4655 job 279 finished using the cpu
At 4660 job 363 arrived
At 4660 job 280 started using the cpu
At 4665 job 280 finished using the cpu
At 4665 job 280 terminated
At 4680 job 364 arrived
At 4680 job 281 started using the cpu
At 4683 job 281 finished using the cpu
At 4686 job 365 arrived
At 4686 job 74 started using the cpu
At 4691 job 74 finished using the cpu
At 4705 job 366 arrived
At 4705 job 282 started using the cpu
At 4706 job 367 arrived
At 4706 job 282 finished using the cpu
At 4726 job 89 started using disk1
At 4726 job 368 arrived
At 4726 job 283 started using the cpu
At 4731 job 283 finished using the cpu
At 4746 job 369 arrived
At 4746 job 284 started using the cpu
At 4749 job 370 arrived
At 4751 job 284 finished using the cpu
At 4758 job 371 arrived
At 4758 job 285 started using the cpu
At 4762 job 372 arrived
At 4762 job 285 finished using the cpu
At 4773 job 373 arrived
At 4773 job 286 started using the cpu
At 4778 job 286 finished using the cpu
At 4797 job 374 arrived
At 4797 job 287 started using the cpu
At 4799 job 287 finished using the cpu
At 4801 job 375 arrived
At 4801 job 75 started using the cpu
At 4802 job 75 finished using the cpu
At 4813 job 89 finished using disk1
At 4826 job 90 started using disk1
At 4826 job 376 arrived
At 4826 job 288 started using the cpu
At 4829 job 288 finished using the cpu
At 4829 job 288 terminated
At 4844 job 377 arrived
At 4844 job 289 started using the cpu
At 4845 job 289 finished using the cpu
At 4851 job 378 arrived
At 4851 job 290 started using the cpu
At 4852 job 90 finished using disk1
At 4856 job 290 finished using the cpu
At 4862 job 24 started using disk1
At 4871 job 379 arrived
At 4871 job 291 started using the cpu
At 4874 job 291 finished using the cpu
At 4874 job 291 terminated
At 4882 job 380 arrived
At 4882 job 292 started using the cpu
At 4884 job 292 finished using the cpu
At 4895 job 381 arrived
At 4895 job 293 started using the cpu
At 4898 job 382 arrived
At 4900 job 293 finished using the cpu
At 4918 job 383 arrived
At 4918 job 76 started using the cpu
At 4919 job 384 arrived
At 4922 job 76 finished using the cpu
At 4937 job 24 finished using disk1
At 4943 job 385 arrived
At 4943 job 294 started using the cpu
At 4948 job 294 finished using the cpu
At 4967 job 386 arrived
At 4967 job 295 started using the cpu
At 4968 job 387 arrived
At 4972 job 295 finished using the cpu
At 4978 job 388 arrived
At 4978 job 296 started using the cpu
At 4980 job 296 finished using the cpu
At 4980 job 296 terminated
At 4990 job 91 started using disk1
At 5003 job 389 arrived
At 5003 job 297 started using the cpu
At 5007 job 297 finished using the cpu
At 5015 job 390 arrived
At 5015 job 298 started using the cpu
At 5017 job 298 finished using the cpu
At 5018 job 391 arrived
At 5018 job 299 started using the cpu
At 5022 job 299 finished using the cpu
At 5022 job 299 terminated
At 5034 job 392 arrived
At 5034 job 77 started using the cpu
At 5037 job 91 finished using disk1
At 5039 job 393 arrived
At 5039 job 77 finished using the cpu
At 5040 job 92 started using disk1
At 5047 job 394 arrived
At 5047 job 300 started using the cpu
At 5049 job 395 arrived
At 5050 job 300 finished using the cpu
At 5065 job 396 arrived
At 5065 job 301 started using the cpu
At 5070 job 301 finished using the cpu
At 5086 job 397 arrived
At 5086 job 302 started using the cpu
At 5091 job 302 finished using the cpu
At 5103 job 398 arrived
At 5103 job 303 started using the cpu
At 5107 job 303 finished using the cpu
At 5107 job 303 terminated
At 5127 job 399 arrived
At 5127 job 304 started using the cpu
At 5130 job 92 finished using disk1
At 5130 job 304 finished using the cpu
At 5130 job 304 terminated
At 5132 job 93 started using disk1
At 5150 job 400 arrived
At 5150 job 305 started using the cpu
At 5152 job 305 finished using the cpu
At 5161 job 401 arrived
At 5161 job 306 started using the cpu
At 5164 job 306 finished using the cpu
At 5175 job 402 arrived
At 5175 job 307 started using the cpu
At 5176 job 307 finished using the cpu
At 5181 job 403 arrived
At 5181 job 308 started using the cpu
At 5183 job 308 finished using the cpu
At 5187 job 93 finished using disk1
At 5191 job 404 arrived
At 5191 job 309 started using the cpu
At 5192 job 94 started using disk1
At 5196 job 309 finished using the cpu
At 5210 job 405 arrived
At 5210 job 310 started using the cpu
At 5215 job 310 finished using the cpu
At 5228 job 406 arrived
At 5228 job 311 started using the cpu
At 5230 job 407 arrived
At 5230 job 311 finished using the cpu
At 5237 job 408 arrived
At 5237 job 312 started using the cpu
At 5241 job 409 arrived
At 5242 job 312 finished using the cpu
At 5243 job 410 arrived
At 5243 job 79 started using the cpu
At 5247 job 411 arrived
At 5247 job 79 finished using the cpu
At 5263 job 94 finished using disk1
At 5269 job 412 arrived
At 5269 job 313 started using the cpu
At 5272 job 313 finished using the cpu
At 5278 job 413 arrived
At 5278 job 314 started using the cpu
At 5279 job 314 finished using the cpu
At 5282 job 2 started using disk1
At 5302 job 414 arrived
At 5302 job 315 started using the cpu
At 5305 job 415 arrived
At 5306 job 315 finished using the cpu
At 5321 job 416 arrived
At 5321 job 80 started using the cpu
At 5322 job 80 finished using the cpu
At 5324 job 2 finished using disk1
At 5328 job 95 started using disk1
At 5344 job 417 arrived
At 5344 job 316 started using the cpu
At 5347 job 418 arrived
At 5347 job 316 finished using the cpu
At 5368 job 419 arrived
At 5368 job 317 started using the cpu
At 5372 job 317 finished using the cpu
At 5379 job 420 arrived
At 5379 job 318 started using the cpu
At 5384 job 318 finished using the cpu
At 5386 job 421 arrived
At 5386 job 319 started using the cpu
At 5390 job 319 finished using the cpu
At 5390 job 319 terminated
At 5394 job 422 arrived
At 5394 job 320 started using the cpu
At 5399 job 320 finished using the cpu
At 5402 job 423 arrived
At 5402 job 82 started using the cpu
At 5407 job 82 finished using the cpu
At 5420 job 424 arrived
At 5420 job 321 started using the cpu
At 5422 job 321 finished using the cpu
At 5425 job 95 finished using disk1
At 5439 job 425 arrived
At 5439 job 322 started using the cpu
At 5440 job 322 finished using the cpu
At 5446 job 96 started using disk1
At 5463 job 426 arrived
At 5463 job 323 started using the cpu
At 5464 job 323 finished using the cpu
At 5483 job 427 arrived
At 5483 job 324 started using the cpu
At 5484 job 324 finished using the cpu
At 5496 job 428 arrived
At 5496 job 325 started using the cpu
At 5499 job 325 finished using the cpu
At 5516 job 429 arrived
At 5516 job 326 started using the cpu
At 5518 job 96 finished using disk1
At 5518 job 326 finished using the cpu
At 5524 job 430 arrived
At 5524 job 327 started using the cpu
At 5527 job 327 finished using the cpu
At 5538 job 431 arrived
At 5538 job 328 started using the cpu
At 5539 job 328 finished using the cpu
At 5544 job 98 started using disk1
At 5561 job 432 arrived
At 5561 job 329 started using the cpu
At 5564 job 329 finished using the cpu
At 5579 job 433 arrived
At 5579 job 9 started using the cpu
At 5582 job 9 finished using the cpu
At 5583 job 434 arrived
At 5583 job 330 started using the cpu
At 5587 job 98 finished using disk1
At 5588 job 435 arrived
At 5588 job 330 finished using the cpu
At 5604 job 99 started using disk1
At 5604 job 436 arrived
At 5604 job 331 started using the cpu
At 5606 job 331 finished using the cpu
At 5612 job 437 arrived
At 5612 job 332 started using the cpu
At 5616 job 332 finished using the cpu
At 5621 job 438 arrived
At 5621 job 333 started using the cpu
At 5626 job 333 finished using the cpu
At 5633 job 99 finished using disk1
At 5635 job 439 arrived
At 5635 job 334 started using the cpu
At 5637 job 334 finished using the cpu
At 5637 job 334 terminated
At 5646 job 440 arrived
At 5646 job 335 started using the cpu
At 5648 job 335 finished using the cpu
At 5654 job 441 arrived
At 5654 job 336 started using the cpu
At 5658 job 336 finished using the cpu
At 5658 job 336 terminated
At 5664 job 442 arrived
At 5664 job 337 started using the cpu
At 5666 job 337 finished using the cpu
At 5668 job 100 started using disk1
At 5687 job 443 arrived
At 5687 job 338 started using the cpu
At 5689 job 338 finished using the cpu
At 5703 job 444 arrived
At 5703 job 339 started using the cpu
At 5704 job 339 finished using the cpu
At 5707 job 100 finished using disk1
At 5710 job 101 started using disk1
At 5712 job 445 arrived
At 5712 job 340 started using the cpu
At 5717 job 340 finished using the cpu
At 5717 job 340 terminated
At 5735 job 446 arrived
At 5735 job 84 started using the cpu
At 5739 job 447 arrived
At 5739 job 84 finished using the cpu
At 5756 job 448 arrived
At 5756 job 341 started using the cpu
At 5758 job 341 finished using the cpu
At 5770 job 449 arrived
At 5770 job 342 started using the cpu
At 5772 job 342 finished using the cpu
At 5788 job 450 arrived
At 5788 job 343 started using the cpu
At 5792 job 343 finished using the cpu
At 5808 job 101 finished using disk1
At 5808 job 451 arrived
At 5808 job 344 started using the cpu
At 5812 job 452 arrived
At 5813 job 344 finished using the cpu
At 5816 job 25 started using disk1
At 5819 job 453 arrived
At 5819 job 345 started using the cpu
At 5821 job 345 finished using the cpu
At 5842 job 454 arrived
At 5842 job 346 started using the cpu
At 5845 job 346 finished using the cpu
At 5857 job 455 arrived
At 5857 job 347 started using the cpu
At 5858 job 347 finished using the cpu
At 5881 job 456 arrived
At 5881 job 348 started using the cpu
At 5882 job 457 arrived
At 5884 job 348 finished using the cpu
At 5884 job 348 terminated
At 5886 job 25 finished using disk1
At 5897 job 458 arrived
At 5897 job 86 started using the cpu
At 5901 job 86 finished using the cpu
At 5904 job 103 started using disk1
At 5910 job 459 arrived
At 5910 job 349 started using the cpu
At 5913 job 349 finished using the cpu
At 5919 job 460 arrived
At 5919 job 350 started using the cpu
At 5920 job 461 arrived
At 5921 job 350 finished using the cpu
At 5929 job 462 arrived
At 5929 job 351 started using the cpu
At 5931 job 351 finished using the cpu
At 5954 job 463 arrived
At 5954 job 352 started using the cpu
At 5959 job 352 finished using the cpu
At 5966 job 464 arrived
At 5966 job 353 started using the cpu
At 5970 job 353 finished using the cpu
At 5986 job 465 arrived
At 5986 job 354 started using the cpu
At 5990 job 354 finished using the cpu
At 5990 job 354 terminated
At 5991 job 103 finished using disk1
At 5994 job 104 started using disk1
At 5996 job 466 arrived
At 5996 job 87 started using the cpu
At 6000 job 467 arrived
At 6001 job 87 finished using the cpu
At 6001 job 87 terminated
At 6022 job 468 arrived
At 6022 job 355 started using the cpu
At 6026 job 355 finished using the cpu
At 6026 job 355 terminated
At 6046 job 469 arrived
At 6046 job 356 started using the cpu
At 6050 job 356 finished using the cpu
At 6059 job 470 arrived
At 6059 job 357 started using the cpu
At 6061 job 357 finished using the cpu
At 6071 job 104 finished using disk1
At 6082 job 471 arrived
At 6082 job 358 started using the cpu
At 6086 job 358 finished using the cpu
At 6104 job 472 arrived
At 6104 job 359 started using the cpu
At 6109 job 359 finished using the cpu
At 6110 job 26 started using disk1
At 6112 job 473 arrived
At 6112 job 360 started using the cpu
At 6113 job 360 finished using the cpu
At 6126 job 474 arrived
At 6126 job 88 started using the cpu
At 6129 job 88 finished using the cpu
At 6151 job 475 arrived
At 6151 job 361 started using the cpu
At 6155 job 361 finished using the cpu
At 6156 job 476 arrived
At 6156 job 362 started using the cpu
At 6161 job 362 finished using the cpu
At 6167 job 477 arrived
At 6167 job 363 started using the cpu
At 6171 job 363 finished using the cpu
At 6181 job 26 finished using disk1
At 6192 job 478 arrived
At 6192 job 364 started using the cpu
At 6194 job 364 finished using the cpu
At 6217 job 479 arrived
At 6217 job 365 started using the cpu
At 6222 job 365 finished using the cpu
At 6229 job 480 arrived
At 6229 job 366 started using the cpu
At 6232 job 366 finished using the cpu
At 6238 job 107 started using disk1
At 6240 job 481 arrived
At 6240 job 367 started using the cpu
At 6241 job 482 arrived
At 6245 job 367 finished using the cpu
At 6257 job 483 arrived
At 6257 job 368 started using the cpu
At 6258 job 368 finished using the cpu
At 6276 job 107 finished using disk1
At 6282 job 109 started using disk1
At 6282 job 484 arrived
At 6282 job 369 started using the cpu
At 6286 job 369 finished using the cpu
At 6292 job 485 arrived
At 6292 job 370 started using the cpu
At 6297 job 486 arrived
At 6297 job 370 finished using the cpu
At 6299 job 487 arrived
At 6299 job 371 started using the cpu
At 6301 job 371 finished using the cpu
At 6301 job 371 terminated
At 6314 job 109 finished using disk1
At 6319 job 488 arrived
At 6319 job 372 started using the cpu
At 6324 job 372 finished using the cpu
At 6334 job 111 started using disk1
At 6340 job 489 arrived
At 6340 job 373 started using the cpu
At 6341 job 373 finished using the cpu
At 6341 job 373 terminated
At 6363 job 490 arrived
At 6363 job 374 started using the cpu
At 6365 job 374 finished using the cpu
At 6375 job 491 arrived
At 6375 job 375 started using the cpu
At 6376 job 375 finished using the cpu
At 6376 job 375 terminated
At 6396 job 492 arrived
At 6396 job 89 started using the cpu
At 6398 job 111 finished using disk1
At 6398 job 89 finished using the cpu
At 6417 job 493 arrived
At 6417 job 376 started using the cpu
At 6418 job 112 started using disk1
At 6418 job 376 finished using the cpu
At 6429 job 494 arrived
At 6429 job 377 started using the cpu
At 6432 job 377 finished using the cpu
At 6432 job 377 terminated
At 6442 job 495 arrived
At 6442 job 378 started using the cpu
At 6444 job 378 finished using the cpu
At 6444 job 378 terminated
At 6460 job 496 arrived
At 6460 job 90 started using the cpu
At 6463 job 90 finished using the cpu
At 6469 job 112 finished using disk1
At 6480 job 497 arrived
At 6480 job 379 started using the cpu
At 6484 job 379 finished using the cpu
At 6498 job 498 arrived
At 6498 job 380 started using the cpu
At 6502 job 113 started using disk1
At 6503 job 380 finished using the cpu
At 6507 job 499 arrived
At 6507 job 381 started using the cpu
At 6511 job 381 finished using the cpu
At 6519 job 500 arrived
At 6519 job 382 started using the cpu
At 6522 job 382 finished using the cpu
At 6529 job 113 finished using disk1
At 6537 job 501 arrived
At 6537 job 383 started using the cpu
At 6540 job 383 finished using the cpu
At 6550 job 114 started using disk1
At 6557 job 502 arrived
At 6557 job 384 started using the cpu
At 6558 job 503 arrived
At 6559 job 384 finished using the cpu
At 6572 job 504 arrived
At 6572 job 24 started using the cpu
At 6573 job 24 finished using the cpu
At 6584 job 505 arrived
At 6584 job 385 started using the cpu
At 6585 job 385 finished using the cpu
At 6591 job 506 arrived
At 6591 job 386 started using the cpu
At 6596 job 386 finished using the cpu
At 6603 job 507 arrived
At 6603 job 387 started using the cpu
At 6605 job 387 finished using the cpu
At 6605 job 387 terminated
At 6617 job 508 arrived
At 6617 job 388 started using the cpu
At 6622 job 388 finished using the cpu
At 6628 job 509 arrived
At 6628 job 389 started using the cpu
At 6630 job 389 finished using the cpu
At 6632 job 510 arrived
At 6632 job 390 started using the cpu
At 6634 job 390 finished using the cpu
At 6639 job 511 arrived
At 6639 job 391 started using the cpu
At 6640 job 114 finished using disk1
At 6644 job 512 arrived
At 6644 job 391 finished using the cpu
At 6644 job 391 terminated
At 6650 job 513 arrived
At 6650 job 392 started using the cpu
At 6654 job 392 finished using the cpu
At 6667 job 514 arrived
At 6667 job 91 started using the cpu
At 6669 job 91 finished using the cpu
At 6682 job 515 arrived
At 6682 job 393 started using the cpu
At 6683 job 516 arrived
At 6686 job 517 arrived
At 6687 job 393 finished using the cpu
At 6695 job 518 arrived
At 6695 job 394 started using the cpu
At 6696 job 115 started using disk1
At 6698 job 394 finished using the cpu
At 6707 job 519 arrived
At 6707 job 395 started using the cpu
At 6709 job 395 finished using the cpu
At 6709 job 395 terminated
At 6718 job 520 arrived
At 6718 job 396 started using the cpu
At 6721 job 396 finished using the cpu
At 6739 job 521 arrived
At 6739 job 397 started using the cpu
At 6743 job 397 finished using the cpu
At 6759 job 115 finished using disk1
At 6763 job 522 arrived
At 6763 job 398 started using the cpu
At 6765 job 398 finished using the cpu
At 6771 job 523 arrived
At 6771 job 399 started using the cpu
At 6774 job 399 finished using the cpu
At 6776 job 27 started using disk1
At 6785 job 524 arrived
At 6785 job 92 started using the cpu
At 6789 job 92 finished using the cpu
At 6794 job 525 arrived
At 6794 job 400 started using the cpu
At 6795 job 400 finished using the cpu
At 6817 job 526 arrived
At 6817 job 401 started using the cpu
At 6822 job 401 finished using the cpu
At 6832 job 27 finished using disk1
At 6842 job 527 arrived
At 6842 job 402 started using the cpu
At 6846 job 402 finished using the cpu
At 6852 job 528 arrived
At 6852 job 403 started using the cpu
At 6856 job 403 finished using the cpu
At 6859 job 529 arrived
At 6859 job 93 started using the cpu
At 6864 job 93 finished using the cpu
At 6872 job 116 started using disk1
At 6876 job 530 arrived
At 6876 job 404 started using the cpu
At 6881 job 404 finished using the cpu
At 6885 job 531 arrived
At 6885 job 405 started using the cpu
At 6887 job 532 arrived
At 6888 job 405 finished using the cpu
At 6909 job 533 arrived
At 6909 job 406 started using the cpu
At 6911 job 406 finished using the cpu
At 6921 job 534 arrived
At 6921 job 407 started using the cpu
At 6924 job 407 finished using the cpu
At 6928 job 535 arrived
At 6928 job 408 started using the cpu
At 6929 job 536 arrived
At 6930 job 408 finished using the cpu
At 6930 job 408 terminated
At 6943 job 116 finished using disk1
At 6943 job 537 arrived
At 6943 job 409 started using the cpu
At 6946 job 409 finished using the cpu
At 6956 job 538 arrived
At 6956 job 410 started using the cpu
At 6958 job 410 finished using the cpu
At 6966 job 539 arrived
At 6966 job 411 started using the cpu
At 6970 job 411 finished using the cpu
At 6978 job 117 started using disk1
At 6987 job 540 arrived
At 6987 job 94 started using the cpu
At 6988 job 94 finished using the cpu
At 7009 job 541 arrived
At 7009 job 412 started using the cpu
At 7013 job 412 finished using the cpu
At 7022 job 542 arrived
At 7022 job 413 started using the cpu
At 7024 job 413 finished using the cpu
At 7026 job 543 arrived
At 7026 job 414 started using the cpu
At 7027 job 117 finished using disk1
At 7027 job 414 finished using the cpu
At 7028 job 118 started using disk1
At 7028 job 544 arrived
At 7028 job 415 started using the cpu
At 7030 job 545 arrived
At 7033 job 415 finished using the cpu
At 7052 job 546 arrived
At 7052 job 416 started using the cpu
At 7054 job 547 arrived
At 7056 job 416 finished using the cpu
At 7060 job 548 arrived
At 7060 job 2 started using the cpu
At 7061 job 549 arrived
At 7065 job 2 finished using the cpu
At 7073 job 550 arrived
At 7073 job 417 started using the cpu
At 7078 job 417 finished using the cpu
At 7089 job 551 arrived
At 7089 job 418 started using the cpu
At 7090 job 418 finished using the cpu
At 7090 job 418 terminated
At 7106 job 118 finished using disk1
At 7110 job 552 arrived
At 7110 job 419 started using the cpu
At 7113 job 419 finished using the cpu
At 7122 job 120 started using disk1
At 7130 job 553 arrived
At 7130 job 420 started using the cpu
At 7134 job 420 finished using the cpu
At 7134 job 420 terminated
At 7138 job 554 arrived
At 7138 job 421 started using the cpu
At 7142 job 421 finished using the cpu
At 7154 job 555 arrived
At 7154 job 422 started using the cpu
At 7159 job 422 finished using the cpu
At 7165 job 556 arrived
At 7165 job 423 started using the cpu
At 7167 job 423 finished using the cpu
At 7179 job 557 arrived
At 7179 job 424 started using the cpu
At 7182 job 424 finished using the cpu
At 7187 job 558 arrived
At 7187 job 95 started using the cpu
At 7191 job 95 finished using the cpu
At 7202 job 559 arrived
At 7202 job 425 started using the cpu
At 7204 job 425 finished using the cpu
At 7211 job 560 arrived
At 7211 job 426 started using the cpu
At 7213 job 426 finished using the cpu
At 7216 job 120 finished using disk1
At 7236 job 561 arrived
At 7236 job 427 started using the cpu
At 7238 job 427 finished using the cpu
At 7246 job 121 started using disk1
At 7258 job 562 arrived
At 7258 job 428 started using the cpu
At 7260 job 428 finished using the cpu
At 7260 job 428 terminated
At 7265 job 563 arrived
At 7265 job 429 started using the cpu
At 7266 job 429 finished using the cpu
At 7279 job 564 arrived
At 7279 job 96 started using the cpu
At 7283 job 96 finished using the cpu
At 7283 job 96 terminated
At 7284 job 565 arrived
At 7284 job 430 started using the cpu
At 7285 job 430 finished using the cpu
At 7286 job 121 finished using disk1
At 7300 job 122 started using disk1
At 7301 job 566 arrived
At 7301 job 431 started using the cpu
At 7305 job 431 finished using the cpu
At 7315 job 567 arrived
At 7315 job 432 started using the cpu
At 7318 job 432 finished using the cpu
At 7331 job 568 arrived
At 7331 job 433 started using the cpu
At 7334 job 433 finished using the cpu
At 7334 job 433 terminated
At 7337 job 569 arrived
At 7337 job 434 started using the cpu
At 7338 job 434 finished using the cpu
At 7345 job 570 arrived
At 7345 job 98 started using the cpu
At 7349 job 98 finished using the cpu
At 7351 job 571 arrived
At 7351 job 435 started using the cpu
At 7354 job 435 finished using the cpu
At 7360 job 572 arrived
At 7360 job 436 started using the cpu
At 7364 job 436 finished using the cpu
At 7370 job 122 finished using disk1
At 7375 job 573 arrived
At 7375 job 437 started using the cpu
At 7376 job 437 finished using the cpu
At 7379 job 574 arrived
At 7379 job 438 started using the cpu
At 7381 job 438 finished using the cpu
At 7384 job 123 started using disk1
At 7389 job 575 arrived
At 7389 job 99 started using the cpu
At 7391 job 99 finished using the cpu
At 7408 job 576 arrived
At 7408 job 439 started using the cpu
At 7410 job 439 finished using the cpu
At 7415 job 577 arrived
At 7415 job 440 started using the cpu
At 7420 job 440 finished using the cpu
At 7439 job 578 arrived
At 7439 job 441 started using the cpu
At 7440 job 123 finished using disk1
At 7443 job 441 finished using the cpu
At 7444 job 579 arrived
At 7444 job 442 started using the cpu
At 7448 job 442 finished using the cpu
At 7458 job 580 arrived
At 7458 job 443 started using the cpu
At 7460 job 443 finished using the cpu
At 7477 job 581 arrived
At 7477 job 444 started using the cpu
At 7478 job 444 finished using the cpu
At 7479 job 582 arrived
At 7479 job 100 started using the cpu
At 7481 job 100 finished using the cpu
At 7481 job 100 terminated
At 7498 job 583 arrived
At 7498 job 445 started using the cpu
At 7500 job 445 finished using the cpu
At 7506 job 124 started using disk1
At 7522 job 584 arrived
At 7522 job 446 started using the cpu
At 7526 job 446 finished using the cpu
At 7537 job 585 arrived
At 7537 job 447 started using the cpu
At 7539 job 447 finished using the cpu
At 7545 job 586 arrived
At 7545 job 448 started using the cpu
At 7546 job 448 finished using the cpu
At 7561 job 587 arrived
At 7561 job 449 started using the cpu
At 7566 job 449 finished using the cpu
At 7576 job 588 arrived
At 7576 job 450 started using the cpu
At 7579 job 450 finished using the cpu
At 7579 job 450 terminated
At 7590 job 124 finished using disk1
At 7597 job 589 arrived
At 7597 job 101 started using the cpu
At 7600 job 101 finished using the cpu
At 7606 job 590 arrived
At 7606 job 451 started using the cpu
At 7607 job 451 finished using the cpu
At 7610 job 591 arrived
At 7610 job 452 started using the cpu
At 7612 job 452 finished using the cpu
At 7617 job 592 arrived
At 7617 job 453 started using the cpu
At 7622 job 453 finished using the cpu
At 7634 job 28 started using disk1
At 7642 job 593 arrived
At 7642 job 454 started using the cpu
At 7644 job 454 finished using the cpu
At 7660 job 594 arrived
At 7660 job 455 started using the cpu
At 7662 job 455 finished using the cpu
At 7668 job 595 arrived
At 7668 job 456 started using the cpu
At 7672 job 456 finished using the cpu
At 7679 job 28 finished using disk1
At 7685 job 596 arrived
At 7685 job 457 started using the cpu
At 7686 job 457 finished using the cpu
At 7693 job 597 arrived
At 7693 job 25 started using the cpu
At 7698 job 25 finished using the cpu
At 7698 job 25 terminated
At 7708 job 36 started using disk2
At 7715 job 598 arrived
At 7715 job 458 started using the cpu
At 7719 job 458 finished using the cpu
At 7730 job 125 started using disk1
At 7734 job 599 arrived
At 7734 job 459 started using the cpu
At 7739 job 459 finished using the cpu
At 7752 job 600 arrived
At 7752 job 460 started using the cpu
At 7755 job 460 finished using the cpu
At 7765 job 601 arrived
At 7765 job 461 started using the cpu
At 7768 job 461 finished using the cpu
At 7773 job 602 arrived
At 7773 job 462 started using the cpu
At 7775 job 462 finished using the cpu
At 7775 job 462 terminated
At 7783 job 603 arrived
At 7783 job 463 started using the cpu
At 7787 job 463 finished using the cpu
At 7792 job 36 finished using disk1
At 7796 job 604 arrived
At 7796 job 464 started using the cpu
At 7801 job 464 finished using the cpu
At 7813 job 605 arrived
At 7813 job 465 started using the cpu
At 7815 job 465 finished using the cpu
At 7825 job 125 finished using disk1
At 7835 job 606 arrived
At 7835 job 103 started using the cpu
At 7840 job 103 finished using the cpu
At 7847 job 607 arrived
At 7847 job 466 started using the cpu
At 7850 job 466 finished using the cpu
At 7858 job 608 arrived
At 7858 job 467 started using the cpu
At 7859 job 467 finished using the cpu
At 7864 job 37 started using disk2
At 7864 job 609 arrived
At 7864 job 468 started using the cpu
At 7867 job 468 finished using the cpu
At 7879 job 610 arrived
At 7879 job 469 started using the cpu
At 7880 job 469 finished using the cpu
At 7884 job 611 arrived
At 7884 job 470 started using the cpu
At 7889 job 470 finished using the cpu
At 7889 job 470 terminated
At 7896 job 612 arrived
At 7896 job 104 started using the cpu
At 7897 job 104 finished using the cpu
At 7919 job 613 arrived
At 7919 job 471 started using the cpu
At 7920 job 471 finished using the cpu
At 7932 job 614 arrived
At 7932 job 472 started using the cpu
At 7933 job 37 finished using disk1
At 7934 job 472 finished using the cpu
At 7936 job 615 arrived
At 7936 job 473 started using the cpu
At 7939 job 473 finished using the cpu
At 7961 job 616 arrived
At 7961 job 474 started using the cpu
At 7965 job 474 finished using the cpu
At 7965 job 474 terminated
At 7972 job 39 started using disk2
At 7972 job 617 arrived
At 7972 job 475 started using the cpu
At 7976 job 475 finished using the cpu
At 7976 job 475 terminated
At 7983 job 618 arrived
At 7983 job 476 started using the cpu
At 7984 job 476 finished using the cpu
At 7984 job 476 terminated
At 7992 job 619 arrived
At 7992 job 477 started using the cpu
At 7997 job 477 finished using the cpu
At 8013 job 39 finished using disk1
At 8014 job 40 started using disk2
At 8015 job 620 arrived
At 8015 job 26 started using the cpu
At 8020 job 26 finished using the cpu
At 8030 job 621 arrived
At 8030 job 478 started using the cpu
At 8034 job 478 finished using the cpu
At 8041 job 622 arrived
At 8041 job 479 started using the cpu
At 8042 job 479 finished using the cpu
At 8042 job 479 terminated
At 8058 job 623 arrived
At 8058 job 480 started using the cpu
At 8061 job 480 finished using the cpu
At 8076 job 40 finished using disk1
At 8077 job 624 arrived
At 8077 job 481 started using the cpu
At 8080 job 41 started using disk2
At 8081 job 481 finished using the cpu
At 8081 job 481 terminated
At 8083 job 625 arrived
At 8083 job 482 started using the cpu
At 8084 job 482 finished using the cpu
At 8094 job 626 arrived
At 8094 job 483 started using the cpu
At 8097 job 483 finished using the cpu
At 8097 job 483 terminated
At 8098 job 627 arrived
At 8098 job 107 started using the cpu
At 8100 job 107 finished using the cpu
At 8108 job 628 arrived
At 8108 job 484 started using the cpu
At 8111 job 484 finished using the cpu
At 8115 job 41 finished using disk1
At 8133 job 629 arrived
At 8133 job 485 started using the cpu
At 8137 job 485 finished using the cpu
At 8140 job 43 started using disk2
At 8142 job 630 arrived
At 8142 job 486 started using the cpu
At 8145 job 486 finished using the cpu
At 8147 job 631 arrived
At 8147 job 487 started using the cpu
At 8150 job 487 finished using the cpu
At 8165 job 632 arrived
At 8165 job 109 started using the cpu
At 8169 job 633 arrived
At 8169 job 109 finished using the cpu
At 8169 job 109 terminated
At 8188 job 43 finished using disk1
At 8192 job 634 arrived
At 8192 job 488 started using the cpu
At 8195 job 488 finished using the cpu
At 8198 job 635 arrived
At 8198 job 489 started using the cpu
At 8200 job 489 finished using the cpu
At 8200 job 489 terminated
At 8209 job 636 arrived
At 8209 job 490 started using the cpu
At 8211 job 637 arrived
At 8214 job 490 finished using the cpu
At 8220 job 638 arrived
At 8220 job 491 started using the cpu
At 8221 job 639 arrived
At 8223 job 491 finished using the cpu
At 8229 job 640 arrived
At 8229 job 492 started using the cpu
At 8230 job 44 started using disk2
At 8234 job 492 finished using the cpu
At 8248 job 641 arrived
At 8248 job 111 started using the cpu
At 8249 job 111 finished using the cpu
At 8263 job 642 arrived
At 8263 job 493 started using the cpu
At 8268 job 493 finished using the cpu
At 8271 job 44 finished using disk1
At 8278 job 8 started using disk2
At 8283 job 643 arrived
At 8283 job 494 started using the cpu
At 8285 job 494 finished using the cpu
At 8292 job 644 arrived
At 8292 job 495 started using the cpu
At 8296 job 495 finished using the cpu
At 8300 job 645 arrived
At 8300 job 496 started using the cpu
At 8303 job 496 finished using the cpu
At 8313 job 646 arrived
At 8313 job 112 started using the cpu
At 8315 job 112 finished using the cpu
At 8316 job 8 finished using disk1
At 8338 job 647 arrived
At 8338 job 497 started using the cpu
At 8339 job 648 arrived
At 8341 job 497 finished using the cpu
At 8345 job 649 arrived
At 8345 job 498 started using the cpu
At 8348 job 498 finished using the cpu
At 8353 job 650 arrived
At 8353 job 499 started using the cpu
At 8354 job 499 finished using the cpu
At 8364 job 45 started using disk2
At 8378 job 651 arrived
At 8378 job 500 started using the cpu
At 8380 job 500 finished using the cpu
At 8380 job 500 terminated
At 8397 job 652 arrived
At 8397 job 113 started using the cpu
At 8398 job 113 finished using the cpu
At 8422 job 653 arrived
At 8422 job 501 started using the cpu
At 8424 job 45 finished using disk1
At 8426 job 501 finished using the cpu
At 8438 job 46 started using disk2
At 8440 job 654 arrived
At 8440 job 502 started using the cpu
At 8443 job 502 finished using the cpu
At 8448 job 655 arrived
At 8448 job 503 started using the cpu
At 8450 job 503 finished using the cpu
At 8454 job 656 arrived
At 8454 job 504 started using the cpu
At 8456 job 504 finished using the cpu
At 8478 job 657 arrived
At 8478 job 505 started using the cpu
At 8482 job 505 finished using the cpu
At 8499 job 658 arrived
At 8499 job 506 started using the cpu
At 8500 job 659 arrived
At 8501 job 506 finished using the cpu
At 8513 job 46 finished using disk1
At 8517 job 660 arrived
At 8517 job 507 started using the cpu
At 8518 job 507 finished using the cpu
At 8536 job 47 started using disk2
At 8539 job 661 arrived
At 8539 job 508 started using the cpu
At 8541 job 662 arrived
At 8544 job 508 finished using the cpu
At 8561 job 663 arrived
At 8561 job 509 started using the cpu
At 8563 job 509 finished using the cpu
At 8572 job 664 arrived
At 8572 job 510 started using the cpu
At 8574 job 510 finished using the cpu
At 8577 job 665 arrived
At 8577 job 511 started using the cpu
At 8581 job 511 finished using the cpu
At 8593 job 47 finished using disk1
At 8598 job 666 arrived
At 8598 job 114 started using the cpu
At 8600 job 114 finished using the cpu
At 8603 job 667 arrived
At 8603 job 512 started using the cpu
At 8605 job 512 finished using the cpu
At 8605 job 512 terminated
At 8618 job 48 started using disk2
At 8618 job 668 arrived
At 8618 job 513 started using the cpu
At 8620 job 513 finished using the cpu
At 8640 job 669 arrived
At 8640 job 514 started using the cpu
At 8643 job 48 finished using disk1
At 8644 job 514 finished using the cpu
At 8658 job 49 started using disk2
At 8664 job 670 arrived
At 8664 job 515 started using the cpu
At 8669 job 515 finished using the cpu
At 8671 job 671 arrived
At 8671 job 516 started using the cpu
At 8672 job 516 finished using the cpu
At 8693 job 672 arrived
At 8693 job 517 started using the cpu
At 8695 job 517 finished using the cpu
At 8711 job 673 arrived
At 8711 job 518 started using the cpu
At 8714 job 518 finished using the cpu
At 8727 job 674 arrived
At 8727 job 519 started using the cpu
At 8729 job 519 finished using the cpu
At 8730 job 675 arrived
At 8730 job 520 started using the cpu
At 8733 job 520 finished using the cpu
At 8739 job 49 finished using disk1
At 8742 job 3 started using disk2
At 8751 job 676 arrived
At 8751 job 521 started using the cpu
At 8756 job 677 arrived
At 8756 job 521 finished using the cpu
At 8781 job 678 arrived
At 8781 job 115 started using the cpu
At 8784 job 679 arrived
At 8784 job 115 finished using the cpu
At 8784 job 115 terminated
At 8802 job 3 finished using disk1
At 8809 job 680 arrived
At 8809 job 522 started using the cpu
At 8814 job 522 finished using the cpu
At 8830 job 681 arrived
At 8830 job 523 started using the cpu
At 8831 job 523 finished using the cpu
At 8834 job 50 started using disk2
At 8850 job 682 arrived
At 8850 job 524 started using the cpu
At 8852 job 524 finished using the cpu
At 8865 job 683 arrived
At 8865 job 525 started using the cpu
At 8866 job 525 finished using the cpu
At 8872 job 684 arrived
At 8872 job 526 started using the cpu
At 8875 job 526 finished using the cpu
At 8875 job 526 terminated
At 8895 job 685 arrived
At 8895 job 27 started using the cpu
At 8897 job 686 arrived
At 8899 job 27 finished using the cpu
At 8903 job 687 arrived
At 8903 job 527 started using the cpu
At 8908 job 527 finished using the cpu
At 8921 job 688 arrived
At 8921 job 528 started using the cpu
At 8925 job 528 finished using the cpu
At 8932 job 50 finished using disk1
At 8944 job 689 arrived
At 8944 job 529 started using the cpu
At 8945 job 529 finished using the cpu
At 8954 job 690 arrived
At 8954 job 530 started using the cpu
At 8959 job 530 finished using the cpu
At 8959 job 530 terminated
At 8965 job 691 arrived
At 8965 job 531 started using the cpu
At 8966 job 531 finished using the cpu
At 8982 job 51 started using disk2
At 8985 job 692 arrived
At 8985 job 532 started using the cpu
At 8988 job 532 finished using the cpu
At 8988 job 532 terminated
At 9002 job 693 arrived
At 9002 job 533 started using the cpu
At 9003 job 533 finished using the cpu
At 9013 job 694 arrived
At 9013 job 534 started using the cpu
At 9016 job 695 arrived
At 9017 job 534 finished using the cpu
At 9017 job 534 terminated
At 9023 job 696 arrived
At 9023 job 535 started using the cpu
At 9026 job 697 arrived
At 9028 job 535 finished using the cpu
At 9028 job 535 terminated
At 9043 job 51 finished using disk1
At 9048 job 698 arrived
At 9048 job 536 started using the cpu
At 9052 job 536 finished using the cpu
At 9055 job 699 arrived
At 9055 job 116 started using the cpu
At 9058 job 116 finished using the cpu
At 9059 job 700 arrived
At 9059 job 537 started using the cpu
At 9061 job 701 arrived
At 9064 job 537 finished using the cpu
At 9064 job 702 arrived
At 9064 job 538 started using the cpu
At 9069 job 538 finished using the cpu
At 9074 job 52 started using disk2
At 9074 job 703 arrived
At 9074 job 539 started using the cpu
At 9079 job 539 finished using the cpu
At 9081 job 704 arrived
At 9081 job 540 started using the cpu
At 9085 job 540 finished using the cpu
At 9104 job 705 arrived
At 9104 job 541 started using the cpu
At 9109 job 541 finished using the cpu
At 9114 job 706 arrived
At 9114 job 542 started using the cpu
At 9119 job 542 finished using the cpu
At 9126 job 707 arrived
At 9126 job 543 started using the cpu
At 9128 job 543 finished using the cpu
At 9135 job 52 finished using disk1
At 9139 job 708 arrived
At 9139 job 117 started using the cpu
At 9143 job 117 finished using the cpu
At 9148 job 709 arrived
At 9148 job 544 started using the cpu
At 9150 job 11 started using disk2
At 9151 job 544 finished using the cpu
At 9151 job 544 terminated
At 9173 job 710 arrived
At 9173 job 545 started using the cpu
At 9177 job 545 finished using the cpu
At 9177 job 545 terminated
At 9183 job 711 arrived
At 9183 job 546 started using the cpu
At 9186 job 546 finished using the cpu
At 9197 job 712 arrived
At 9197 job 547 started using the cpu
At 9199 job 547 finished using the cpu
At 9199 job 547 terminated
At 9205 job 713 arrived
At 9205 job 548 started using the cpu
At 9206 job 11 finished using disk1
At 9208 job 548 finished using the cpu
At 9219 job 714 arrived
At 9219 job 549 started using the cpu
At 9221 job 549 finished using the cpu
At 9233 job 715 arrived
At 9233 job 550 started using the cpu
At 9234 job 550 finished using the cpu
At 9246 job 53 started using disk2
At 9258 job 716 arrived
At 9258 job 551 started using the cpu
At 9261 job 551 finished using the cpu
At 9283 job 717 arrived
At 9283 job 118 started using the cpu
At 9287 job 718 arrived
At 9287 job 118 finished using the cpu
At 9299 job 719 arrived
At 9299 job 552 started using the cpu
At 9300 job 552 finished using the cpu
At 9319 job 53 finished using disk1
At 9324 job 720 arrived
At 9324 job 553 started using the cpu
At 9328 job 553 finished using the cpu
At 9338 job 721 arrived
At 9338 job 554 started using the cpu
At 9340 job 554 finished using the cpu
At 9342 job 722 arrived
At 9342 job 555 started using the cpu
At 9343 job 555 finished using the cpu
At 9358 job 723 arrived
At 9358 job 556 started using the cpu
At 9362 job 556 finished using the cpu
At 9362 job 556 terminated
At 9366 job 54 started using disk2
At 9378 job 724 arrived
At 9378 job 557 started using the cpu
At 9382 job 557 finished using the cpu
At 9392 job 725 arrived
At 9392 job 558 started using the cpu
At 9395 job 558 finished using the cpu
At 9402 job 726 arrived
At 9402 job 559 started using the cpu
At 9403 job 559 finished using the cpu
At 9411 job 54 finished using disk1
At 9412 job 12 started using disk2
At 9413 job 727 arrived
At 9413 job 560 started using the cpu
At 9418 job 560 finished using the cpu
At 9422 job 728 arrived
At 9422 job 120 started using the cpu
At 9423 job 120 finished using the cpu
At 9442 job 12 finished using disk1
At 9442 job 729 arrived
At 9442 job 561 started using the cpu
At 9444 job 561 finished using the cpu
At 9444 job 561 terminated
At 9447 job 730 arrived
At 9447 job 562 started using the cpu
At 9450 job 562 finished using the cpu
At 9450 job 562 terminated
At 9452 job 731 arrived
At 9452 job 563 started using the cpu
At 9455 job 563 finished using the cpu
At 9462 job 55 started using disk2
At 9468 job 732 arrived
At 9468 job 564 started using the cpu
At 9473 job 564 finished using the cpu
At 9491 job 733 arrived
At 9491 job 565 started using the cpu
At 9492 job 565 finished using the cpu
At 9492 job 565 terminated
At 9494 job 734 arrived
At 9494 job 121 started using the cpu
At 9495 job 121 finished using the cpu
At 9495 job 121 terminated
At 9517 job 55 finished using disk1
At 9517 job 735 arrived
At 9517 job 566 started using the cpu
At 9522 job 566 finished using the cpu
At 9522 job 566 terminated
At 9524 job 56 started using disk2
At 9534 job 736 arrived
At 9534 job 567 started using the cpu
At 9535 job 737 arrived
At 9535 job 567 finished using the cpu
At 9543 job 738 arrived
At 9543 job 568 started using the cpu
At 9545 job 568 finished using the cpu
At 9547 job 739 arrived
At 9547 job 569 started using the cpu
At 9550 job 740 arrived
At 9550 job 569 finished using the cpu
At 9565 job 56 finished using disk1
At 9566 job 741 arrived
At 9566 job 570 started using the cpu
At 9571 job 570 finished using the cpu
At 9578 job 742 arrived
At 9578 job 571 started using the cpu
At 9583 job 743 arrived
At 9583 job 571 finished using the cpu
At 9598 job 13 started using disk2
At 9603 job 744 arrived
At 9603 job 572 started using the cpu
At 9608 job 572 finished using the cpu
At 9627 job 745 arrived
At 9627 job 122 started using the cpu
At 9632 job 746 arrived
At 9632 job 122 finished using the cpu
At 9637 job 747 arrived
At 9637 job 573 started using the cpu
At 9640 job 573 finished using the cpu
At 9657 job 748 arrived
At 9657 job 574 started using the cpu
At 9659 job 574 finished using the cpu
At 9679 job 749 arrived
At 9679 job 575 started using the cpu
At 9683 job 750 arrived
At 9683 job 575 finished using the cpu
At 9683 job 575 terminated
At 9686 job 13 finished using disk1
At 9690 job 57 started using disk2
At 9691 job 751 arrived
At 9691 job 576 started using the cpu
At 9694 job 576 finished using the cpu
At 9703 job 752 arrived
At 9703 job 577 started using the cpu
At 9707 job 753 arrived
At 9708 job 577 finished using the cpu
At 9710 job 754 arrived
At 9710 job 578 started using the cpu
At 9714 job 578 finished using the cpu
At 9727 job 755 arrived
At 9727 job 123 started using the cpu
At 9729 job 123 finished using the cpu
At 9736 job 57 finished using disk1
At 9738 job 756 arrived
At 9738 job 579 started using the cpu
At 9741 job 579 finished using the cpu
At 9748 job 757 arrived
At 9748 job 580 started using the cpu
At 9753 job 580 finished using the cpu
At 9764 job 758 arrived
At 9764 job 581 started using the cpu
At 9765 job 581 finished using the cpu
At 9768 job 58 started using disk2
At 9781 job 759 arrived
At 9781 job 582 started using the cpu
At 9783 job 582 finished using the cpu
At 9798 job 58 finished using disk1
At 9798 job 760 arrived
At 9798 job 583 started using the cpu
At 9800 job 59 started using disk2
At 9803 job 583 finished using the cpu
At 9803 job 583 terminated
At 9820 job 761 arrived
At 9820 job 584 started using the cpu
At 9823 job 584 finished using the cpu
At 9823 job 584 terminated
At 9824 job 762 arrived
At 9824 job 585 started using the cpu
At 9826 job 585 finished using the cpu
At 9843 job 763 arrived
At 9843 job 586 started using the cpu
At 9845 job 586 finished using the cpu
At 9866 job 764 arrived
At 9866 job 587 started using the cpu
At 9867 job 587 finished using the cpu
At 9867 job 587 terminated
At 9872 job 765 arrived
At 9872 job 588 started using the cpu
At 9875 job 588 finished using the cpu
At 9875 job 588 terminated
At 9891 job 59 finished using disk1
At 9896 job 61 started using disk2
At 9897 job 766 arrived
At 9897 job 124 started using the cpu
At 9900 job 124 finished using the cpu
At 9916 job 767 arrived
At 9916 job 589 started using the cpu
At 9917 job 589 finished using the cpu
At 9930 job 768 arrived
At 9930 job 590 started using the cpu
At 9933 job 590 finished using the cpu
At 9933 job 590 terminated
At 9938 job 769 arrived
At 9938 job 591 started using the cpu
At 9942 job 591 finished using the cpu
At 9962 job 770 arrived
At 9962 job 592 started using the cpu
At 9967 job 592 finished using the cpu
At 9975 job 61 finished using disk1
At 9983 job 771 arrived
At 9983 job 593 started using the cpu
At 9986 job 593 finished using the cpu
At 10007 job 772 arrived
At 10007 job 594 started using the cpu
At 10008 job 594 finished using the cpu
At 10014 job 63 started using disk2
At 10024 job 773 arrived
At 10024 job 595 started using the cpu
At 10025 job 595 finished using the cpu
At 10036 job 774 arrived
At 10036 job 28 started using the cpu
At 10040 job 28 finished using the cpu
At 10045 job 775 arrived
At 10045 job 596 started using the cpu
At 10049 job 596 finished using the cpu
At 10056 job 776 arrived
At 10056 job 597 started using the cpu
At 10059 job 597 finished using the cpu
At 10059 job 597 terminated
At 10062 job 777 arrived
At 10062 job 598 started using the cpu
At 10063 job 63 finished using disk1
At 10066 job 598 finished using the cpu
At 10078 job 64 started using disk2
At 10081 job 778 arrived
At 10081 job 599 started using the cpu
At 10082 job 599 finished using the cpu
At 10087 job 779 arrived
At 10087 job 600 started using the cpu
At 10088 job 600 finished using the cpu
At 10108 job 780 arrived
At 10108 job 601 started using the cpu
At 10109 job 601 finished using the cpu
At 10119 job 781 arrived
At 10119 job 602 started using the cpu
At 10121 job 602 finished using the cpu
At 10128 job 64 finished using disk1
At 10134 job 782 arrived
At 10134 job 603 started using the cpu
At 10135 job 603 finished using the cpu
At 10140 job 14 started using disk2
At 10144 job 783 arrived
At 10144 job 36 started using the cpu
At 10148 job 36 finished using the cpu
At 10148 job 36 terminated
At 10162 job 784 arrived
At 10162 job 604 started using the cpu
At 10166 job 604 finished using the cpu
At 10174 job 785 arrived
At 10174 job 605 started using the cpu
At 10177 job 605 finished using the cpu
At 10190 job 14 finished using disk1
At 10194 job 786 arrived
At 10194 job 125 started using the cpu
At 10197 job 125 finished using the cpu
At 10197 job 125 terminated
At 10201 job 787 arrived
At 10201 job 606 started using the cpu
At 10206 job 606 finished using the cpu
At 10216 job 788 arrived
At 10216 job 607 started using the cpu
At 10221 job 607 finished using the cpu
At 10238 job 789 arrived
At 10238 job 608 started using the cpu
At 10240 job 608 finished using the cpu
At 10258 job 790 arrived
At 10258 job 609 started using the cpu
At 10263 job 791 arrived
At 10263 job 609 finished using the cpu
At 10270 job 792 arrived
At 10270 job 610 started using the cpu
At 10271 job 793 arrived
At 10275 job 610 finished using the cpu
At 10276 job 794 arrived
At 10276 job 611 started using the cpu
At 10278 job 611 finished using the cpu
At 10297 job 795 arrived
At 10297 job 612 started using the cpu
At 10302 job 612 finished using the cpu
At 10302 job 612 terminated
At 10304 job 65 started using disk2
At 10318 job 796 arrived
At 10318 job 613 started using the cpu
At 10321 job 613 finished using the cpu
At 10340 job 797 arrived
At 10340 job 614 started using the cpu
At 10342 job 614 finished using the cpu
At 10359 job 798 arrived
At 10359 job 37 started using the cpu
At 10360 job 37 finished using the cpu
At 10368 job 799 arrived
At 10368 job 615 started using the cpu
At 10369 job 800 arrived
At 10373 job 615 finished using the cpu
At 10390 job 801 arrived
At 10390 job 616 started using the cpu
At 10392 job 65 finished using disk1
At 10394 job 616 finished using the cpu
At 10411 job 802 arrived
At 10411 job 617 started using the cpu
At 10414 job 617 finished using the cpu
At 10430 job 66 started using disk2
At 10436 job 803 arrived
At 10436 job 618 started using the cpu
At 10439 job 618 finished using the cpu
At 10439 job 618 terminated
At 10457 job 804 arrived
At 10457 job 619 started using the cpu
At 10458 job 805 arrived
At 10460 job 806 arrived
At 10462 job 619 finished using the cpu
At 10464 job 66 finished using disk1
At 10481 job 807 arrived
At 10481 job 39 started using the cpu
At 10484 job 67 started using disk2
At 10486 job 39 finished using the cpu
At 10489 job 808 arrived
At 10489 job 620 started using the cpu
At 10491 job 620 finished using the cpu
At 10496 job 809 arrived
At 10496 job 621 started using the cpu
At 10498 job 621 finished using the cpu
At 10516 job 810 arrived
At 10516 job 622 started using the cpu
At 10518 job 622 finished using the cpu
At 10518 job 622 terminated
At 10531 job 67 finished using disk1
At 10539 job 811 arrived
At 10539 job 623 started using the cpu
At 10541 job 623 finished using the cpu
At 10544 job 227 started using disk2
At 10561 job 812 arrived
At 10561 job 40 started using the cpu
At 10562 job 40 finished using the cpu
At 10579 job 813 arrived
At 10579 job 624 started using the cpu
At 10580 job 624 finished using the cpu
At 10580 job 624 terminated
At 10591 job 814 arrived
At 10591 job 625 started using the cpu
At 10594 job 625 finished using the cpu
At 10598 job 815 arrived
At 10598 job 626 started using the cpu
At 10602 job 626 finished using the cpu
At 10607 job 816 arrived
At 10607 job 627 started using the cpu
At 10608 job 627 finished using the cpu
At 10608 job 627 terminated
At 10612 job 817 arrived
At 10612 job 628 started using the cpu
At 10614 job 628 finished using the cpu
At 10623 job 818 arrived
At 10623 job 41 started using the cpu
At 10624 job 41 finished using the cpu
At 10639 job 227 finished using disk1
At 10640 job 819 arrived
At 10640 job 629 started using the cpu
At 10644 job 228 started using disk2
At 10644 job 629 finished using the cpu
At 10654 job 820 arrived
At 10654 job 630 started using the cpu
At 10657 job 630 finished using the cpu
At 10661 job 821 arrived
At 10661 job 631 started using the cpu
At 10665 job 822 arrived
At 10665 job 631 finished using the cpu
At 10690 job 823 arrived
At 10690 job 632 started using the cpu
At 10691 job 824 arrived
At 10694 job 632 finished using the cpu
At 10700 job 825 arrived
At 10700 job 633 started using the cpu
At 10703 job 633 finished using the cpu
At 10709 job 826 arrived
At 10709 job 43 started using the cpu
At 10710 job 43 finished using the cpu
At 10733 job 827 arrived
At 10733 job 634 started using the cpu
At 10738 job 634 finished using the cpu
At 10740 job 228 finished using disk1
At 10744 job 229 started using disk2
At 10750 job 828 arrived
At 10750 job 635 started using the cpu
At 10754 job 635 finished using the cpu
At 10765 job 829 arrived
At 10765 job 636 started using the cpu
At 10769 job 636 finished using the cpu
At 10774 job 830 arrived
At 10774 job 637 started using the cpu
At 10778 job 637 finished using the cpu
At 10796 job 831 arrived
At 10796 job 638 started using the cpu
At 10797 job 638 finished using the cpu
At 10797 job 638 terminated
At 10803 job 832 arrived
At 10803 job 639 started using the cpu
At 10804 job 639 finished using the cpu
At 10818 job 833 arrived
At 10818 job 640 started using the cpu
At 10821 job 640 finished using the cpu
At 10834 job 834 arrived
At 10834 job 641 started using the cpu
At 10835 job 229 finished using disk1
At 10835 job 641 finished using the cpu
At 10835 job 641 terminated
At 10843 job 835 arrived
At 10843 job 642 started using the cpu
At 10844 job 232 started using disk2
At 10848 job 642 finished using the cpu
At 10862 job 836 arrived
At 10862 job 44 started using the cpu
At 10866 job 44 finished using the cpu
At 10866 job 44 terminated
At 10873 job 837 arrived
At 10873 job 643 started using the cpu
At 10877 job 643 finished using the cpu
At 10890 job 838 arrived
At 10890 job 644 started using the cpu
At 10892 job 644 finished using the cpu
At 10892 job 644 terminated
At 10897 job 839 arrived
At 10897 job 645 started using the cpu
At 10900 job 645 finished using the cpu
At 10914 job 840 arrived
At 10914 job 646 started using the cpu
At 10917 job 646 finished using the cpu
At 10921 job 232 finished using disk1
At 10928 job 21 started using disk2
At 10929 job 841 arrived
At 10929 job 8 started using the cpu
At 10934 job 8 finished using the cpu
At 10952 job 842 arrived
At 10952 job 647 started using the cpu
At 10955 job 647 finished using the cpu
At 10955 job 647 terminated
At 10962 job 843 arrived
At 10962 job 648 started using the cpu
At 10964 job 648 finished using the cpu
At 10979 job 844 arrived
At 10979 job 649 started using the cpu
At 10981 job 649 finished using the cpu
At 10989 job 845 arrived
At 10989 job 650 started using the cpu
At 10991 job 650 finished using the cpu
At 11008 job 846 arrived
At 11008 job 651 started using the cpu
At 11012 job 847 arrived
At 11013 job 21 finished using disk1
At 11013 job 651 finished using the cpu
At 11019 job 848 arrived
At 11019 job 652 started using the cpu
At 11021 job 652 finished using the cpu
At 11036 job 235 started using disk2
At 11044 job 849 arrived
At 11044 job 653 started using the cpu
At 11046 job 653 finished using the cpu
At 11047 job 850 arrived
At 11047 job 45 started using the cpu
At 11050 job 45 finished using the cpu
At 11070 job 851 arrived
At 11070 job 654 started using the cpu
At 11075 job 852 arrived
At 11075 job 654 finished using the cpu
At 11085 job 853 arrived
At 11085 job 655 started using the cpu
At 11089 job 655 finished using the cpu
At 11102 job 235 finished using disk1
At 11110 job 854 arrived
At 11110 job 656 started using the cpu
At 11113 job 656 finished using the cpu
At 11115 job 855 arrived
At 11115 job 657 started using the cpu
At 11117 job 657 finished using the cpu
At 11117 job 657 terminated
At 11128 job 236 started using disk2
At 11133 job 856 arrived
At 11133 job 658 started using the cpu
At 11135 job 658 finished using the cpu
At 11150 job 857 arrived
At 11150 job 659 started using the cpu
At 11152 job 659 finished using the cpu
At 11173 job 858 arrived
At 11173 job 46 started using the cpu
At 11176 job 46 finished using the cpu
At 11193 job 859 arrived
At 11193 job 660 started using the cpu
At 11196 job 660 finished using the cpu
At 11196 job 660 terminated
At 11218 job 860 arrived
At 11218 job 661 started using the cpu
At 11223 job 661 finished using the cpu
At 11224 job 236 finished using disk1
At 11232 job 237 started using disk2
At 11241 job 861 arrived
At 11241 job 662 started using the cpu
At 11245 job 662 finished using the cpu
At 11248 job 862 arrived
At 11248 job 663 started using the cpu
At 11250 job 663 finished using the cpu
At 11264 job 863 arrived
At 11264 job 664 started using the cpu
At 11269 job 664 finished using the cpu
At 11275 job 864 arrived
At 11275 job 665 started using the cpu
At 11278 job 665 finished using the cpu
At 11284 job 865 arrived
At 11284 job 47 started using the cpu
At 11287 job 47 finished using the cpu
At 11302 job 866 arrived
At 11302 job 666 started using the cpu
At 11305 job 237 finished using disk1
At 11305 job 666 finished using the cpu
At 11312 job 867 arrived
At 11312 job 667 started using the cpu
At 11315 job 667 finished using the cpu
At 11318 job 868 arrived
At 11318 job 668 started using the cpu
At 11323 job 869 arrived
At 11323 job 668 finished using the cpu
At 11332 job 238 started using disk2
At 11333 job 870 arrived
At 11333 job 669 started using the cpu
At 11334 job 669 finished using the cpu
At 11357 job 871 arrived
At 11357 job 48 started using the cpu
At 11360 job 48 finished using the cpu
At 11374 job 238 finished using disk1
At 11376 job 872 arrived
At 11376 job 670 started using the cpu
At 11378 job 23 started using disk2
At 11378 job 670 finished using the cpu
At 11378 job 670 terminated
At 11401 job 873 arrived
At 11401 job 671 started using the cpu
At 11403 job 874 arrived
At 11404 job 671 finished using the cpu
At 11417 job 875 arrived
At 11417 job 672 started using the cpu
At 11421 job 672 finished using the cpu
At 11440 job 876 arrived
At 11440 job 673 started using the cpu
At 11444 job 673 finished using the cpu
At 11444 job 673 terminated
At 11450 job 877 arrived
At 11450 job 674 started using the cpu
At 11453 job 674 finished using the cpu
At 11463 job 23 finished using disk1
At 11471 job 878 arrived
At 11471 job 675 started using the cpu
At 11472 job 879 arrived
At 11474 job 880 arrived
At 11476 job 675 finished using the cpu
At 11478 job 240 started using disk2
At 11481 job 881 arrived
At 11481 job 49 started using the cpu
At 11482 job 49 finished using the cpu
At 11482 job 49 terminated
At 11489 job 882 arrived
At 11489 job 676 started using the cpu
At 11494 job 676 finished using the cpu
At 11509 job 883 arrived
At 11509 job 677 started using the cpu
At 11511 job 884 arrived
At 11513 job 677 finished using the cpu
At 11513 job 677 terminated
At 11514 job 885 arrived
At 11514 job 678 started using the cpu
At 11515 job 678 finished using the cpu
At 11515 job 678 terminated
At 11524 job 886 arrived
At 11524 job 679 started using the cpu
At 11528 job 679 finished using the cpu
At 11536 job 240 finished using disk1
At 11536 job 887 arrived
At 11536 job 3 started using the cpu
At 11541 job 3 finished using the cpu
At 11544 job 241 started using disk2
At 11548 job 888 arrived
At 11548 job 680 started using the cpu
At 11553 job 680 finished using the cpu
At 11573 job 889 arrived
At 11573 job 681 started using the cpu
At 11577 job 681 finished using the cpu
At 11585 job 890 arrived
At 11585 job 682 started using the cpu
At 11590 job 682 finished using the cpu
At 11607 job 891 arrived
At 11607 job 683 started using the cpu
At 11609 job 683 finished using the cpu
At 11610 job 241 finished using disk1
At 11615 job 892 arrived
At 11615 job 684 started using the cpu
At 11620 job 684 finished using the cpu
At 11626 job 242 started using disk2
At 11630 job 893 arrived
At 11630 job 685 started using the cpu
At 11632 job 685 finished using the cpu
At 11633 job 894 arrived
At 11633 job 686 started using the cpu
At 11635 job 686 finished using the cpu
At 11641 job 895 arrived
At 11641 job 687 started using the cpu
At 11645 job 687 finished using the cpu
At 11659 job 896 arrived
At 11659 job 688 started using the cpu
At 11664 job 688 finished using the cpu
At 11664 job 688 terminated
At 11677 job 897 arrived
At 11677 job 50 started using the cpu
At 11679 job 50 finished using the cpu
At 11679 job 50 terminated
At 11699 job 898 arrived
At 11699 job 689 started using the cpu
At 11703 job 689 finished using the cpu
At 11710 job 242 finished using disk1
At 11716 job 243 started using disk2
At 11720 job 899 arrived
At 11720 job 690 started using the cpu
At 11721 job 690 finished using the cpu
At 11734 job 900 arrived
At 11734 job 691 started using the cpu
At 11737 job 691 finished using the cpu
At 11737 job 691 terminated
At 11755 job 901 arrived
At 11755 job 692 started using the cpu
At 11756 job 692 finished using the cpu
At 11767 job 902 arrived
At 11767 job 693 started using the cpu
At 11768 job 693 finished using the cpu
At 11781 job 903 arrived
At 11781 job 694 started using the cpu
At 11784 job 694 finished using the cpu
At 11797 job 243 finished using disk1
At 11797 job 904 arrived
At 11797 job 695 started using the cpu
At 11801 job 695 finished using the cpu
At 11802 job 245 started using disk2
At 11820 job 905 arrived
At 11820 job 696 started using the cpu
At 11824 job 906 arrived
At 11824 job 696 finished using the cpu
At 11834 job 907 arrived
At 11834 job 697 started using the cpu
At 11835 job 697 finished using the cpu
At 11835 job 697 terminated
At 11845 job 908 arrived
At 11845 job 51 started using the cpu
At 11849 job 51 finished using the cpu
At 11866 job 909 arrived
At 11866 job 698 started using the cpu
At 11871 job 698 finished using the cpu
At 11891 job 910 arrived
At 11891 job 699 started using the cpu
At 11893 job 699 finished using the cpu
At 11893 job 699 terminated
At 11902 job 245 finished using disk1
At 11916 job 911 arrived
At 11916 job 700 started using the cpu
At 11918 job 247 started using disk2
At 11919 job 700 finished using the cpu
At 11920 job 912 arrived
At 11920 job 701 started using the cpu
At 11923 job 701 finished using the cpu
At 11938 job 913 arrived
At 11938 job 702 started using the cpu
At 11943 job 702 finished using the cpu
At 11963 job 914 arrived
At 11963 job 703 started using the cpu
At 11968 job 703 finished using the cpu
At 11971 job 915 arrived
At 11971 job 704 started using the cpu
At 11972 job 704 finished using the cpu
At 11978 job 916 arrived
At 11978 job 705 started using the cpu
At 11983 job 705 finished using the cpu
At 11984 job 917 arrived
At 11984 job 706 started using the cpu
At 11987 job 706 finished using the cpu
At 11996 job 247 finished using disk1
At 12002 job 918 arrived
At 12002 job 707 started using the cpu
At 12003 job 707 finished using the cpu
At 12017 job 919 arrived
At 12017 job 52 started using the cpu
At 12022 job 52 finished using the cpu
At 12032 job 920 arrived
At 12032 job 708 started using the cpu
At 12035 job 708 finished using the cpu
At 12048 job 921 arrived
At 12048 job 709 started using the cpu
At 12053 job 709 finished using the cpu
At 12070 job 922 arrived
At 12070 job 710 started using the cpu
At 12074 job 710 finished using the cpu
At 12074 job 710 terminated
At 12090 job 923 arrived
At 12090 job 711 started using the cpu
At 12093 job 711 finished using the cpu
At 12100 job 248 started using disk2
At 12106 job 924 arrived
At 12106 job 712 started using the cpu
At 12109 job 712 finished using the cpu
At 12118 job 925 arrived
At 12118 job 713 started using the cpu
At 12121 job 713 finished using the cpu
At 12121 job 713 terminated
At 12136 job 926 arrived
At 12136 job 11 started using the cpu
At 12138 job 248 finished using disk1
At 12139 job 11 finished using the cpu
At 12139 job 11 terminated
At 12161 job 927 arrived
At 12161 job 714 started using the cpu
At 12163 job 714 finished using the cpu
At 12163 job 714 terminated
At 12172 job 249 started using disk2
At 12179 job 928 arrived
At 12179 job 715 started using the cpu
